<?xml version="1.0" ?>
<!-- =================================================================================== -->
<!-- |    This document was autogenerated by xacro from inmoov_shadow_hand_v2.urdf.xacro | -->
<!-- |    EDITING THIS FILE BY HAND IS NOT RECOMMENDED                                 | -->
<!-- =================================================================================== -->
<robot name="inmoov" xmlns:body="http://playerstage.sourceforge.net/gazebo/xmlschema/#body" xmlns:controller="http://playerstage.sourceforge.net/gazebo/xmlschema/#controller" xmlns:geom="http://playerstage.sourceforge.net/gazebo/xmlschema/#geom" xmlns:interface="http://playerstage.sourceforge.net/gazebo/xmlschema/#interface" xmlns:joint="http://playerstage.sourceforge.net/gazebo/xmlschema/#slider" xmlns:sensor="http://playerstage.sourceforge.net/gazebo/xmlschema/#sensor" xmlns:xacro="http://ros.org/wiki/xacro">
  <!--xacro:property name="pi" value="3.1415926539"/-->
  <!-- meshlab steps taken from http://gazebosim.org/tutorials?tut=inertia -->
  <!-- assume material density is 1.0g per 1.0cm^2 -->
  <!-- ABS is 1.04g per 1.0cm^3 -->
  <!-- PLA is 1.25g per 1.0cm^3 -->
  <!-- <xacro:include filename="$(find inmoov_description)/urdf/inmoov.gazebo" /> -->
  <!-- usage: e.g. ${M_PI/4} -->
  <material name="Blue">
    <color rgba="0.0 0.0 0.8 1.0"/>
  </material>
  <material name="Green">
    <color rgba="0.0 0.8 0.0 1.0"/>
  </material>
  <material name="BiotacGreen">
    <color rgba="0.31 0.85 0.42 1.0"/>
  </material>
  <material name="Grey">
    <color rgba="0.2 0.2 0.2 1.0"/>
  </material>
  <material name="LightGrey">
    <color rgba="0.6 0.6 0.6 1.0"/>
  </material>
  <material name="Red">
    <color rgba="0.8 0.0 0.0 1.0"/>
  </material>
  <material name="White">
    <color rgba="1.0 1.0 1.0 1.0"/>
  </material>
  <!-- <xacro:include filename="$(find sr_description)/other/xacro/gazebo/gazebo.urdf.xacro"/> -->
  <!-- usage: e.g. ${M_PI/4} -->
  <link name="world"/>
  <joint name="fixed" type="fixed">
    <parent link="world"/>
    <child link="base_link"/>
  </joint>
  <link name="base_link">
    <visual>
      <geometry>
        <cylinder length="0.11" radius="0.26"/>
      </geometry>
      <origin rpy="0 0 0" xyz="0 0 0.055"/>
      <material name="cbase">
        <color rgba="0.1 0.1 0.1 1"/>
      </material>
    </visual>
  </link>
  <joint name="base_to_pedestal_link" type="fixed">
    <parent link="base_link"/>
    <child link="pedestal_link"/>
    <origin rpy="0 0 0" xyz="0 0 0"/>
  </joint>
  <link name="pedestal_link">
    <visual>
      <geometry>
        <cylinder length="0.94" radius="0.0254"/>
      </geometry>
      <origin rpy="0 0 0" xyz="0 0 0.58"/>
      <material name="cbase">
        <color rgba="0.1 0.1 0.1 1"/>
      </material>
    </visual>
  </link>
  <link name="head_tilt_link">
    <visual>
      <geometry>
        <mesh filename="package://inmoov_meshes/meshes/virtual.stl" scale="0.001 0.001 0.001"/>
      </geometry>
      <origin rpy="0 0 3.1415" xyz="0 0 0"/>
      <material name="cframe">
        <color rgba="0.40 0.40 0.40 1"/>
      </material>
    </visual>
    <inertial>
      <mass value="0.001"/>
      <inertia ixx="1.66667e-10" ixy="0.0" ixz="0.0" iyy="1.66667e-10" iyz="0.0" izz="1.66667e-10"/>
    </inertial>
  </link>
  <joint name="pedestal_to_mid_stomach_joint" type="fixed">
    <parent link="pedestal_link"/>
    <child link="mid_stomach_link"/>
    <origin rpy="0 0 0" xyz="0 0 0"/>
  </joint>
  <link name="mid_stomach_link">
    <visual>
      <geometry>
        <mesh filename="package://inmoov_meshes/meshes/mid_stomach.stl" scale="0.001 0.001 0.001"/>
      </geometry>
      <origin rpy="0 0 0" xyz="0 0 1.152"/>
      <material name="cframe">
        <color rgba="0.40 0.40 0.40 1"/>
      </material>
    </visual>
    <inertial>
      <mass value="1710.217625"/>
      <inertia ixx="10.129861632" ixy="0.001797694125" ixz="0.205381024" iyy="4.40146688" iyz="-0.000721074" izz="10.623296512"/>
    </inertial>
  </link>
  <link name="disk_link">
    <visual>
      <geometry>
        <mesh filename="package://inmoov_meshes/meshes/disk.stl" scale="0.001 0.001 0.001"/>
      </geometry>
      <origin rpy="0 0 0" xyz="0 0 0"/>
      <material name="ccover">
        <color rgba="0.75 0.75 0.75 1.0"/>
      </material>
    </visual>
    <inertial>
      <mass value="178.96734375"/>
      <inertia ixx="0.518276192" ixy="-3.94440735e-07" ixz="0.012957092" iyy="0.264527408" iyz="1.5683143555e-05" izz="0.268095952"/>
    </inertial>
  </link>
  <link name="top_stomach_link">
    <visual>
      <geometry>
        <mesh filename="package://inmoov_meshes/meshes/top_stomach.stl" scale="0.001 0.001 0.001"/>
      </geometry>
      <origin rpy="0 0 0" xyz="0 0 0"/>
      <material name="cframe">
        <color rgba="0.40 0.40 0.40 1"/>
      </material>
    </visual>
    <inertial>
      <mass value="1144.88975"/>
      <inertia ixx="5.824147968" ixy="0.00452986" ixz="-0.222818176" iyy="4.174386432" iyz="0.00410783" izz="5.962789376"/>
    </inertial>
  </link>
  <link name="torso_link">
    <visual>
      <geometry>
        <mesh filename="package://inmoov_meshes/meshes/torso.stl" scale="0.001 0.001 0.001"/>
      </geometry>
      <origin rpy="0 0 0" xyz="0 0 0"/>
      <material name="cframe">
        <color rgba="0.40 0.40 0.40 1"/>
      </material>
    </visual>
    <inertial>
      <mass value="1923.29375"/>
      <inertia ixx="35.26709248" ixy="0.0069580865" ixz="0.730539008" iyy="25.724428288" iyz="-0.01522677" izz="13.365055488"/>
    </inertial>
  </link>
  <link name="kinect2_link">
    <visual>
      <geometry>
        <mesh filename="package://inmoov_meshes/meshes/kinectone.stl" scale="0.001 0.001 0.001"/>
      </geometry>
      <origin rpy="1.57 0 0" xyz="0 0 0"/>
      <material name="ckinect">
        <color rgba="0.1 0.1 0.1 1"/>
      </material>
    </visual>
    <inertial>
      <mass value="790.8319375"/>
      <inertia ixx="0.539265728" ixy="-0.008770675" ixz="-0.0023443175" iyy="3.865038592" iyz="0.025915652" izz="3.969101824"/>
    </inertial>
  </link>
  <link name="chestplate_link">
    <visual>
      <geometry>
        <mesh filename="package://inmoov_meshes/meshes/chest.stl" scale="0.001 0.001 0.001"/>
      </geometry>
      <origin rpy="0 0 0" xyz="0 0 0"/>
      <material name="ccover">
        <color rgba="0.75 0.75 0.75 1.0"/>
      </material>
    </visual>
    <inertial>
      <mass value="755.6806875"/>
      <inertia ixx="7.996578816" ixy="-0.0004753828125" ixz="-0.051810308" iyy="3.795706624" iyz="0.011253427" izz="4.511691776"/>
    </inertial>
  </link>
  <!-- <joint name="waist_pan_joint" type="revolute">
   <axis xyz="0 0 1"/>
   <limit effort="1000.0" lower="${waist_pan_joint_lower}" upper="${waist_pan_joint_upper}" velocity="${waist_pan_joint_velocity}" />
   <origin rpy="0 0 0" xyz="0 0 1.152"/>
    <parent link="mid_stomach_link"/>
    <child link="top_stomach_link"/>
  </joint> -->
  <joint name="waist_pan_joint" type="fixed">
    <origin rpy="0 0 0" xyz="0 0 1.152"/>
    <parent link="mid_stomach_link"/>
    <child link="top_stomach_link"/>
  </joint>
  <joint name="disk_joint" type="fixed">
    <origin rpy="0 0 0" xyz="0.046 0 0.09"/>
    <parent link="top_stomach_link"/>
    <child link="disk_link"/>
  </joint>
  <!-- <joint name="waist_roll_joint" type="revolute">
   <axis xyz="1 0 0"/>
   <limit effort="1000.0" lower="${waist_roll_joint_lower}" upper="${waist_roll_joint_upper}" velocity="${waist_roll_joint_velocity}" />
   <origin rpy="0 0 0" xyz="0 0 0.11"/>
    <parent link="top_stomach_link"/>
    <child link="torso_link"/>
  </joint> -->
  <joint name="waist_roll_joint" type="fixed">
    <origin rpy="0 0 0" xyz="0 0 0.11"/>
    <parent link="top_stomach_link"/>
    <child link="torso_link"/>
  </joint>
  <joint name="chestplate_joint" type="fixed">
    <origin rpy="0 0 0" xyz="0.042 0 0.025"/>
    <parent link="torso_link"/>
    <child link="chestplate_link"/>
  </joint>
  <joint name="kinect2_joint" type="fixed">
    <origin rpy="-1.57 0 -1.57" xyz="0 0 0.066"/>
    <parent link="torso_link"/>
    <child link="kinect2_link"/>
  </joint>
  <joint name="head_roll_joint" type="revolute">
    <axis xyz="1 0 0"/>
    <limit effort="1000.0" lower="-1.57079632679" upper="1.57079632679" velocity="1745.32925199"/>
    <origin rpy="0 0 3.1415" xyz="-0.0315  -0.001 0.4551"/>
    <parent link="torso_link"/>
    <child link="head_tilt_link"/>
  </joint>
  <joint name="head_tilt_joint" type="revolute">
    <axis xyz="0 1 0"/>
    <limit effort="1000.0" lower="-1.57079632679" upper="1.57079632679" velocity="1745.32925199"/>
    <origin rpy="0 0 3.1415" xyz="0 0 0"/>
    <parent link="head_tilt_link"/>
    <child link="head_base_link"/>
  </joint>
  <link name="head_base_link">
    <visual>
      <geometry>
        <mesh filename="package://inmoov_meshes/meshes/head_base.stl" scale="0.001 0.001 0.001"/>
      </geometry>
      <origin rpy="0 0 0" xyz="0 0 0"/>
      <material name="cframe">
        <color rgba="0.40 0.40 0.40 1"/>
      </material>
    </visual>
    <inertial>
      <mass value="43.50228125"/>
      <inertia ixx="0.025681996" ixy="1.829096875e-05" ixz="-0.00079066275" iyy="0.017327208" iyz="9.602263672e-06" izz="0.03535528"/>
    </inertial>
  </link>
  <link name="head_link">
    <visual>
      <geometry>
        <mesh filename="package://inmoov_meshes/meshes/head.stl" scale="0.001 0.001 0.001"/>
      </geometry>
      <origin rpy="0 0 0" xyz="0 0 0"/>
      <material name="cframe">
        <color rgba="0.40 0.40 0.40 1"/>
      </material>
    </visual>
    <inertial>
      <mass value="120.499460938"/>
      <inertia ixx="0.09250868" ixy="-0.000123085367188" ixz="-0.0078627105" iyy="0.150815008" iyz="0.0002850305625" izz="0.201933552"/>
    </inertial>
  </link>
  <link name="jaw_link">
    <visual>
      <geometry>
        <mesh filename="package://inmoov_meshes/meshes/jaw.stl" scale="0.001 0.001 0.001"/>
      </geometry>
      <origin rpy="0 0 0" xyz="0 0 0"/>
      <material name="ccover">
        <color rgba="0.75 0.75 0.75 1.0"/>
      </material>
    </visual>
    <inertial>
      <mass value="58.767261719"/>
      <inertia ixx="0.147272256" ixy="7.553278125e-05" ixz="0.055060208" iyy="0.134112088" iyz="-1.2159836914e-05" izz="0.156998304"/>
    </inertial>
  </link>
  <link name="skull_link">
    <visual>
      <geometry>
        <mesh filename="package://inmoov_meshes/meshes/skull.stl" scale="0.001 0.001 0.001"/>
      </geometry>
      <origin rpy="0 0 0" xyz="0 0 0"/>
      <material name="ccover">
        <color rgba="0.75 0.75 0.75 1.0"/>
      </material>
    </visual>
    <inertial>
      <mass value="422.3130625"/>
      <inertia ixx="1.82323712" ixy="0.006736614" ixz="0.115768256" iyy="2.48802176" iyz="-0.0004186136875" izz="2.440409856"/>
    </inertial>
  </link>
  <link name="left_ear_link">
    <visual>
      <geometry>
        <mesh filename="package://inmoov_meshes/meshes/earleftv1.stl" scale="0.001 0.001 0.001"/>
      </geometry>
      <origin rpy="0 0 0" xyz="0 0 0"/>
      <material name="cframe">
        <color rgba="0.40 0.40 0.40 1"/>
      </material>
    </visual>
    <inertial>
      <mass value="85.197960938"/>
      <inertia ixx="0.04423034" ixy="-0.001262894" ixz="0.005220882" iyy="0.08046712" iyz="-0.00048412846875" izz="0.04075106"/>
    </inertial>
  </link>
  <link name="right_ear_link">
    <visual>
      <geometry>
        <mesh filename="package://inmoov_meshes/meshes/earrightv1.stl" scale="0.001 0.001 0.001"/>
      </geometry>
      <origin rpy="0 0 0" xyz="0 0 0"/>
      <material name="cframe">
        <color rgba="0.40 0.40 0.40 1"/>
      </material>
    </visual>
    <inertial>
      <mass value="85.17540625"/>
      <inertia ixx="0.044218692" ixy="0.00126241425" ixz="0.0052192235" iyy="0.080448136" iyz="0.00048353196875" izz="0.040740816"/>
    </inertial>
  </link>
  <joint name="head_pan_joint" type="revolute">
    <axis xyz="0 0 1"/>
    <limit effort="1000.0" lower="-1.57079632679" upper="1.57079632679" velocity="1745.32925199"/>
    <origin rpy="0 0 0" xyz="0 0 0.0245"/>
    <parent link="head_base_link"/>
    <child link="head_link"/>
  </joint>
  <joint name="jaw_joint" type="fixed">
    <origin rpy="0 0.09 0" xyz="0.0375 0.0005 0.0437"/>
    <parent link="head_link"/>
    <child link="jaw_link"/>
  </joint>
  <joint name="skull_joint" type="fixed">
    <origin rpy="0 0 0" xyz="0.044 0 -0.0245"/>
    <parent link="head_link"/>
    <child link="skull_link"/>
  </joint>
  <joint name="left_ear_joint" type="fixed">
    <origin rpy="0 0 0" xyz="0.035 0.056 0.0437"/>
    <parent link="head_link"/>
    <child link="left_ear_link"/>
  </joint>
  <joint name="right_ear_joint" type="fixed">
    <origin rpy="0 0 0" xyz="0.035 -0.056 0.0437"/>
    <parent link="head_link"/>
    <child link="right_ear_link"/>
  </joint>
  <link name="face_link">
    <visual>
      <geometry>
        <mesh filename="package://inmoov_meshes/meshes/face.stl" scale="0.001 0.001 0.001"/>
      </geometry>
      <origin rpy="0 0 0" xyz="0 0 0"/>
      <material name="ccover">
        <color rgba="0.75 0.75 0.75 1.0"/>
      </material>
    </visual>
    <inertial>
      <mass value="46.55903125"/>
      <inertia ixx="0.060878272" ixy="6.9925132812e-05" ixz="0.00126951125" iyy="0.01978544" iyz="1.37124939e-06" izz="0.051128208"/>
    </inertial>
  </link>
  <joint name="eyes_tilt_joint" type="fixed">
    <origin rpy="0 0 0" xyz="0 0 0"/>
    <parent link="face_link"/>
    <child link="eyesupport_link"/>
  </joint>
  <link name="eyesupport_link">
    <visual>
      <geometry>
        <mesh filename="package://inmoov_meshes/meshes/eyesupport.stl" scale="0.001 0.001 0.001"/>
      </geometry>
      <origin rpy="0 0 0" xyz="0 0 0"/>
      <material name="cframe">
        <color rgba="0.40 0.40 0.40 1"/>
      </material>
    </visual>
    <inertial>
      <mass value="27.550294922"/>
      <inertia ixx="0.02063259" ixy="0.0002853024375" ixz="-0.001400304" iyy="0.016763521" iyz="0.00183966425" izz="0.006981697"/>
    </inertial>
  </link>
  <link name="r_eyesupport_link">
    <visual>
      <geometry>
        <mesh filename="package://inmoov_meshes/meshes/r_eyesupport.stl" scale="0.001 0.001 0.001"/>
      </geometry>
      <origin rpy="0 0 0" xyz="0 0 0"/>
      <material name="cframe">
        <color rgba="0.40 0.40 0.40 1"/>
      </material>
    </visual>
    <inertial>
      <mass value="11.370105469"/>
      <inertia ixx="0.00243239225" ixy="6.936413574e-06" ixz="-1.5166977539e-05" iyy="0.001752612875" iyz="0.0001608714375" izz="0.0008966528125"/>
    </inertial>
  </link>
  <!-- <link name="${side}_camera_link">
    <visual>
      <geometry>
        <mesh filename="package://inmoov_meshes/meshes/camera.stl" scale="0.001 0.001 0.001"/>
      </geometry>
      <origin rpy="0 0 0" xyz="0 0 0"/>
      <xacro:camera_color/>
    </visual>
    <xacro:camera_inertial/>
  </link> -->
  <link name="r_eye_link">
    <visual>
      <geometry>
        <mesh filename="package://inmoov_meshes/meshes/eye.stl" scale="0.001 0.001 0.001"/>
      </geometry>
      <origin rpy="0 0 0" xyz="0 0 0"/>
      <material name="ceyeball">
        <color rgba="0.7 0.7 0.7 1"/>
      </material>
    </visual>
    <inertial>
      <mass value="4.659753906"/>
      <inertia ixx="0.0009137171875" ixy="2.418e-12" ixz="2.11749e-10" iyy="0.0004795756875" iyz="-3.262e-12" izz="0.0004755305"/>
    </inertial>
  </link>
  <link name="r_iris_link">
    <visual>
      <geometry>
        <mesh filename="package://inmoov_meshes/meshes/iris.stl" scale="0.001 0.001 0.001"/>
      </geometry>
      <origin rpy="0 0 0" xyz="0 0 0"/>
      <material name="ciris">
        <color rgba="0.25 0.41 0.88 1"/>
      </material>
    </visual>
    <inertial>
      <mass value="1.026836548"/>
      <inertia ixx="8.5819992188e-05" ixy="-1.07131e-10" ixz="-2.94199e-10" iyy="4.4821710938e-05" iyz="4.19771e-10" izz="4.4822714844e-05"/>
    </inertial>
  </link>
  <!-- <joint name="${side}_camera_joint" type="fixed">
    <origin rpy="0 0 0" xyz="-0.001 0 0"/>
    <parent link="${side}_eyesupport_link"/>
    <child link="${side}_camera_link"/>
  </joint> -->
  <joint name="r_eye_joint" type="fixed">
    <origin rpy="0 0 0" xyz="0.003 0 0"/>
    <parent link="r_eyesupport_link"/>
    <child link="r_eye_link"/>
  </joint>
  <joint name="r_iris_joint" type="fixed">
    <origin rpy="0 0 0" xyz="0.0061 0 0"/>
    <parent link="r_eyesupport_link"/>
    <child link="r_iris_link"/>
  </joint>
  <joint name="eyes_pan_joint" type="fixed">
    <origin rpy="0 0 0" xyz="0 0.033 -0.0036"/>
    <parent link="eyesupport_link"/>
    <child link="r_eyesupport_link"/>
  </joint>
  <link name="l_eyesupport_link">
    <visual>
      <geometry>
        <mesh filename="package://inmoov_meshes/meshes/l_eyesupport.stl" scale="0.001 0.001 0.001"/>
      </geometry>
      <origin rpy="0 0 0" xyz="0 0 0"/>
      <material name="cframe">
        <color rgba="0.40 0.40 0.40 1"/>
      </material>
    </visual>
    <inertial>
      <mass value="11.370105469"/>
      <inertia ixx="0.00243239225" ixy="-6.936314941e-06" ixz="-1.5166963867e-05" iyy="0.00175261275" iyz="-0.0001608714375" izz="0.0008966526875"/>
    </inertial>
  </link>
  <!-- <link name="${side}_camera_link">
    <visual>
      <geometry>
        <mesh filename="package://inmoov_meshes/meshes/camera.stl" scale="0.001 0.001 0.001"/>
      </geometry>
      <origin rpy="0 0 0" xyz="0 0 0"/>
      <xacro:camera_color/>
    </visual>
    <xacro:camera_inertial/>
  </link> -->
  <link name="l_eye_link">
    <visual>
      <geometry>
        <mesh filename="package://inmoov_meshes/meshes/eye.stl" scale="0.001 0.001 0.001"/>
      </geometry>
      <origin rpy="0 0 0" xyz="0 0 0"/>
      <material name="ceyeball">
        <color rgba="0.7 0.7 0.7 1"/>
      </material>
    </visual>
    <inertial>
      <mass value="4.659753906"/>
      <inertia ixx="0.0009137171875" ixy="2.418e-12" ixz="2.11749e-10" iyy="0.0004795756875" iyz="-3.262e-12" izz="0.0004755305"/>
    </inertial>
  </link>
  <link name="l_iris_link">
    <visual>
      <geometry>
        <mesh filename="package://inmoov_meshes/meshes/iris.stl" scale="0.001 0.001 0.001"/>
      </geometry>
      <origin rpy="0 0 0" xyz="0 0 0"/>
      <material name="ciris">
        <color rgba="0.25 0.41 0.88 1"/>
      </material>
    </visual>
    <inertial>
      <mass value="1.026836548"/>
      <inertia ixx="8.5819992188e-05" ixy="-1.07131e-10" ixz="-2.94199e-10" iyy="4.4821710938e-05" iyz="4.19771e-10" izz="4.4822714844e-05"/>
    </inertial>
  </link>
  <!-- <joint name="${side}_camera_joint" type="fixed">
    <origin rpy="0 0 0" xyz="-0.001 0 0"/>
    <parent link="${side}_eyesupport_link"/>
    <child link="${side}_camera_link"/>
  </joint> -->
  <joint name="l_eye_joint" type="fixed">
    <origin rpy="0 0 0" xyz="0.003 0 0"/>
    <parent link="l_eyesupport_link"/>
    <child link="l_eye_link"/>
  </joint>
  <joint name="l_iris_joint" type="fixed">
    <origin rpy="0 0 0" xyz="0.0061 0 0"/>
    <parent link="l_eyesupport_link"/>
    <child link="l_iris_link"/>
  </joint>
  <joint name="l_eye_pan_joint" type="fixed">
    <origin rpy="0 0 0" xyz="0 -0.033 -0.0036"/>
    <parent link="eyesupport_link"/>
    <child link="l_eyesupport_link"/>
  </joint>
  <joint name="face_joint" type="fixed">
    <origin rpy="0 0 0" xyz="0.0637 0 0.079"/>
    <parent link="skull_link"/>
    <child link="face_link"/>
  </joint>
  <link name="r_shoulder_base_link">
    <visual>
      <geometry>
        <mesh filename="package://inmoov_meshes/meshes/r_shoulder_base.stl" scale="0.001 0.001 0.001"/>
      </geometry>
      <origin rpy="0 0 0" xyz="0 0 0"/>
      <material name="cframe">
        <color rgba="0.40 0.40 0.40 1"/>
      </material>
    </visual>
    <inertial>
      <mass value="266.52696875"/>
      <inertia ixx="0.350410112" ixy="-0.0057351625" ixz="-0.011193818" iyy="0.3908856" iyz="0.045447476" izz="0.271458688"/>
    </inertial>
  </link>
  <link name="r_shoulder_link">
    <visual>
      <geometry>
        <mesh filename="package://inmoov_meshes/meshes/r_shoulder.stl" scale="0.001 0.001 0.001"/>
      </geometry>
      <origin rpy="0 0 0" xyz="0 0 0"/>
      <material name="cframe">
        <color rgba="0.40 0.40 0.40 1"/>
      </material>
    </visual>
    <inertial>
      <mass value="322.44334375"/>
      <inertia ixx="0.60134592" ixy="0.00343772975" ixz="-0.011761917" iyy="0.473865856" iyz="-0.114277" izz="0.500951584"/>
    </inertial>
  </link>
  <link name="r_bicep_link_aux_0"/>
  <link name="r_bicep_link_aux_1"/>
  <link name="r_bicep_link">
    <visual>
      <geometry>
        <mesh filename="package://inmoov_meshes/meshes/bicep.stl" scale="0.001 0.001 0.001"/>
      </geometry>
      <origin rpy="0 0 0" xyz="0 0 0"/>
      <material name="cframe">
        <color rgba="0.40 0.40 0.40 1"/>
      </material>
    </visual>
    <inertial>
      <mass value="281.91265625"/>
      <inertia ixx="1.283355392" ixy="-0.000200782203125" ixz="-0.224559104" iyy="1.399255168" iyz="0.0006545236875" izz="0.416621216"/>
    </inertial>
  </link>
  <link name="r_bicepcover_link">
    <visual>
      <geometry>
        <mesh filename="package://inmoov_meshes/meshes/bicepcover.stl" scale="0.001 0.001 0.001"/>
      </geometry>
      <origin rpy="0 0 0" xyz="0 0 0"/>
      <material name="ccover">
        <color rgba="0.75 0.75 0.75 1.0"/>
      </material>
    </visual>
    <inertial>
      <mass value="176.269609375"/>
      <inertia ixx="0.536349632" ixy="0.0009665334375" ixz="-0.069306768" iyy="0.625805568" iyz="0.0005666358125" izz="0.44191648"/>
    </inertial>
  </link>
  <link name="r_forearm_link_aux"/>
  <link name="r_forearm_link">
    <visual>
      <geometry>
        <mesh filename="package://inmoov_meshes/meshes/r_forearm.stl" scale="0.001 0.001 0.001"/>
      </geometry>
      <origin rpy="0 0 0" xyz="0.001 0 0"/>
      <material name="ccover">
        <color rgba="0.75 0.75 0.75 1.0"/>
      </material>
    </visual>
    <inertial>
      <mass value="401.76659375"/>
      <inertia ixx="3.242307584" ixy="0.050011216" ixz="-0.14318512" iyy="3.24251008" iyz="0.086288976" izz="0.58458784"/>
    </inertial>
  </link>
  <joint name="r_shoulder_lift_joint_old" type="fixed">
    <origin rpy="0 0 0" xyz="0 -0.012 -0.04"/>
    <parent link="r_shoulder_base_link"/>
    <child link="r_shoulder_link"/>
  </joint>
  <joint name="r_shoulder_out_joint" type="revolute">
    <axis xyz="1 0 0"/>
    <limit effort="1000.0" lower="-1.57079632679" upper="1.57079632679" velocity="1745.32925199"/>
    <!-- <origin rpy="0 0 0" xyz="0 0 0"/> -->
    <origin rpy="0 0 0" xyz="0 -0.066 -0.06"/>
    <parent link="r_shoulder_link"/>
    <child link="r_bicep_link_aux_0"/>
  </joint>
  <joint name="r_shoulder_lift_joint" type="revolute">
    <axis xyz="0 1 0"/>
    <limit effort="1000.0" lower="-1.57079632679" upper="1.57079632679" velocity="1745.32925199"/>
    <origin rpy="0 0 0" xyz="0 0 0"/>
    <parent link="r_bicep_link_aux_0"/>
    <child link="r_bicep_link_aux_1"/>
  </joint>
  <joint name="r_upper_arm_roll_joint" type="revolute">
    <axis xyz="0 0 1"/>
    <limit effort="1000.0" lower="-1.57079632679" upper="1.57079632679" velocity="1745.32925199"/>
    <origin rpy="0 0 0" xyz="0 0 0"/>
    <parent link="r_bicep_link_aux_1"/>
    <child link="r_bicep_link"/>
  </joint>
  <joint name="r_elbow_flex_joint" type="revolute">
    <axis xyz="0 1 0"/>
    <limit effort="1000.0" lower="-3.14159265359" upper="0.0" velocity="1745.32925199"/>
    <origin rpy="0 0 0" xyz="-0.054 -0.009 -0.2621"/>
    <parent link="r_bicep_link"/>
    <child link="r_forearm_link_aux"/>
  </joint>
  <joint name="r_elbow_roll_joint" type="revolute">
    <axis xyz="0 0 1"/>
    <limit effort="1000.0" lower="-1.57079632679" upper="1.57079632679" velocity="1745.32925199"/>
    <origin rpy="0 0 0" xyz="0.0 0 0.0"/>
    <parent link="r_forearm_link_aux"/>
    <child link="r_forearm_link"/>
  </joint>
  <joint name="r_bicepcover_joint" type="fixed">
    <origin rpy="0 0 0" xyz="0 0 0"/>
    <parent link="r_bicep_link"/>
    <child link="r_bicepcover_link"/>
  </joint>
  <!-- <joint name="r_shoulder_out_joint" type="revolute">
   <axis xyz="1 0 0"/>
   <limit effort="1000.0" lower="${r_shoulder_out_joint_lower}" upper="${r_shoulder_out_joint_upper}" velocity="${r_shoulder_out_joint_velocity}" />
   <origin rpy="0 0 0" xyz="0 -0.14 0.3"/>
   <parent link="torso_link"/>
   <child link="r_shoulder_base_link"/>
  </joint> -->
  <joint name="r_shoulder_out_joint_old" type="fixed">
    <origin rpy="0 0 0" xyz="0 -0.14 0.3"/>
    <parent link="torso_link"/>
    <child link="r_shoulder_base_link"/>
  </joint>
  <!-- shadow hand -->
  <link name="r_hand_link"/>
  <!-- <joint name="r_wrist_roll_joint" type="revolute">
      <axis xyz="0 0 1"/>   
      <limit effort="1000.0" lower="${r_wrist_roll_joint_lower}" upper="${r_wrist_roll_joint_upper}" velocity="${r_wrist_roll_joint_velocity}" />  
      <parent link="r_forearm_link" />
      <child link="r_hand_link" />
      <origin rpy="3.14 0 0" xyz="-0.0144 0.01  -0.2885"/>
  </joint> -->
  <!-- move wrist roll to elbow roll for now -->
  <joint name="r_wrist_roll_joint" type="fixed">
    <parent link="r_forearm_link"/>
    <child link="r_hand_link"/>
    <origin rpy="3.14159265359 0 0" xyz="0.0303 -0.00729 -0.302"/>
  </joint>
  <link name="rh_wrist">
    <inertial>
      <origin rpy="0 0 0" xyz="0 0 0.029"/>
      <mass value="0.1"/>
      <inertia ixx="0.000035" ixy="0.0" ixz="0.0" iyy="0.000064" iyz="0.0" izz="0.0000438"/>
    </inertial>
    <visual>
      <origin rpy="0 0 0" xyz="0 0 0"/>
      <geometry name="rh_wrist_visual">
        <mesh filename="package://sr_description/hand/model/wrist.dae" scale="0.001 0.001 0.001"/>
      </geometry>
      <material name="LightGrey"/>
    </visual>
    <collision>
      <origin rpy="1.5708 1.5708 0" xyz="0 0 0"/>
      <geometry name="rh_wrist_collision_geom">
        <cylinder length="0.030" radius="0.0135"/>
      </geometry>
    </collision>
    <collision>
      <origin rpy="0 1.5708 0" xyz="-0.026 0 0.034"/>
      <geometry>
        <cylinder length="0.010" radius="0.011"/>
      </geometry>
    </collision>
    <collision>
      <origin rpy="0 1.5708 0" xyz="0.031 0 0.034"/>
      <geometry>
        <cylinder length="0.010" radius="0.011"/>
      </geometry>
    </collision>
    <collision>
      <origin rpy="0 0.7854 0" xyz="-0.021 0 0.011"/>
      <geometry>
        <box size="0.027 0.018 0.010"/>
      </geometry>
    </collision>
    <collision>
      <origin rpy="0 -0.7854 0" xyz="0.026 0 0.010"/>
      <geometry>
        <box size="0.027 0.018 0.010"/>
      </geometry>
    </collision>
  </link>
  <gazebo reference="rh_wrist">
    <material>Gazebo/White</material>
    <selfCollide>false</selfCollide>
  </gazebo>
  <joint name="rh_WRJ2" type="revolute">
    <parent link="r_hand_link"/>
    <child link="rh_wrist"/>
    <origin rpy="0 0 0" xyz="0 0.0 0.0"/>
    <!-- this is the wrist adduction -->
    <axis xyz="0 1.0 0"/>
    <limit effort="10" lower="-1.0471975512" upper="1.0471975512" velocity="20.0"/>
    <dynamics damping="0.1"/>
  </joint>
  <gazebo reference="rh_WRJ2">
    <provideFeedback>1</provideFeedback>
    <implicitSpringDamper>1</implicitSpringDamper>
  </gazebo>
  <transmission name="rh_wrist_transmission">
    <type>sr_mechanism_model/SimpleTransmission</type>
    <actuator name="rh_WRJ2">
      <mechanicalReduction>1</mechanicalReduction>
    </actuator>
    <joint name="rh_WRJ2">
      <hardwareInterface>EffortJointInterface</hardwareInterface>
      <hardwareInterface>PositionJointInterface</hardwareInterface>
    </joint>
  </transmission>
  <link name="rh_palm_aux">
    <inertial>
      <origin rpy="0 0 0" xyz="0 0 0"/>
      <mass value="0.003"/>
      <inertia ixx="0.00001" ixy="0" ixz="0" iyy="0.00001" iyz="0" izz="0.00001"/>
    </inertial>
  </link>
  <link name="rh_palm">
    <inertial>
      <origin rpy="0 0 0" xyz="0 0 0.035"/>
      <mass value="0.3"/>
      <inertia ixx="0.0003581" ixy="0.0" ixz="0.0" iyy="0.0005287" iyz="0.0" izz="0.000191"/>
    </inertial>
    <visual>
      <origin rpy="0 0 0" xyz="0 0 0"/>
      <geometry name="rh_palm_visual">
        <mesh filename="package://sr_description/hand/model/palm.dae" scale="0.001 0.001 0.001"/>
      </geometry>
      <material name="Grey"/>
    </visual>
    <collision>
      <origin rpy="0 0 0" xyz="0.011 0.0085 0.038"/>
      <geometry name="rh_palm_collision_geom">
        <box size="0.062 0.007 0.098"/>
      </geometry>
    </collision>
    <collision>
      <origin rpy="0 0 0" xyz="-0.002 -0.0035 0.038"/>
      <geometry>
        <box size="0.036 0.017 0.098"/>
      </geometry>
    </collision>
    <!-- palm complement below first finger -->
    <collision>
      <origin rpy="0 0 0" xyz="0.029 -0.0035 0.082"/>
      <geometry>
        <box size="0.026 0.017 0.010"/>
      </geometry>
    </collision>
    <collision>
      <origin rpy="0.2 0 0.25" xyz="0.0265 -0.001 0.070"/>
      <geometry>
        <box size="0.026 0.014 0.018"/>
      </geometry>
    </collision>
    <!-- thumb pulp side -->
    <collision>
      <origin rpy="0 0 0" xyz="0.0315 -0.0085 0.001"/>
      <geometry>
        <box size="0.021 0.027 0.024"/>
      </geometry>
    </collision>
    <!-- thumb pulp central -->
    <collision>
      <origin rpy="0 0 -0.48" xyz="0.0125 -0.015 0.009"/>
      <geometry>
        <box size="0.022 0.005 0.040"/>
      </geometry>
    </collision>
    <!-- above middle finger-->
    <collision>
      <origin rpy="0 0 0" xyz="0.011 0 0.089"/>
      <geometry>
        <box size="0.018 0.024 0.004"/>
      </geometry>
    </collision>
    <!-- metacarpal side-->
    <collision>
      <origin rpy="0 0 0" xyz="-0.03 0 0.009"/>
      <geometry>
        <box size="0.020 0.024 0.040"/>
      </geometry>
    </collision>
  </link>
  <joint name="rh_WRJ1" type="revolute">
    <parent link="rh_wrist"/>
    <child link="rh_palm_aux"/>
    <origin rpy="0 0 0" xyz="0 0 0.03"/>
    <axis xyz="1 0 0"/>
    <!-- this is the wrist flexion -->
    <limit effort="30" lower="-1.57079632679" upper="1.57079632679" velocity="20.0"/>
    <dynamics damping="0.1"/>
  </joint>
  <gazebo reference="rh_WRJ1">
    <provideFeedback>1</provideFeedback>
    <implicitSpringDamper>1</implicitSpringDamper>
  </gazebo>
  <joint name="rh_palm_aux_joint" type="fixed">
    <origin rpy="0 0 0" xyz="0 0.0 0.0"/>
    <parent link="rh_palm_aux"/>
    <child link="rh_palm"/>
  </joint>
  <!-- prefix can be anything but usually is "r_" or  "l_" for right and left hands distinction -->
  <gazebo reference="rh_palm">
    <sensor name="rh_palm_contact" type="contact">
      <always_on>1</always_on>
      <update_rate>1000.0</update_rate>
      <contact>
        <collision>rh_palm_collision</collision>
        <topic>rh_palm_collision</topic>
      </contact>
      <plugin filename="libgazebo_ros_bumper.so" name="rh_palm_gazebo_ros_bumper_controller">
        <alwaysOn>true</alwaysOn>
        <frameName>rh_palm</frameName>
        <updateRate>100.0</updateRate>
        <bumperTopicName>contacts/rh_palm</bumperTopicName>
      </plugin>
    </sensor>
  </gazebo>
  <link name="rh_ffknuckle">
    <inertial>
      <origin rpy="0 0 0" xyz="0 0 0"/>
      <mass value="0.008"/>
      <inertia ixx="0.00000026" ixy="0.0" ixz="0.0" iyy="0.00000026" iyz="0.0" izz="0.00000032"/>
    </inertial>
    <visual>
      <origin rpy="0 0 0" xyz="0 0 0.0005"/>
      <geometry name="rh_ffknuckle_visual">
        <mesh filename="package://sr_description/hand/model/knuckle.dae" scale="0.001 0.001 0.001"/>
      </geometry>
      <material name="LightGrey"/>
    </visual>
    <collision>
      <origin rpy="0 1.5708 0" xyz="0 0 0"/>
      <geometry name="rh_ffknuckle_collision_geom">
        <cylinder length="0.014" radius="0.007"/>
      </geometry>
    </collision>
  </link>
  <joint name="rh_FFJ4" type="revolute">
    <parent link="rh_palm"/>
    <child link="rh_ffknuckle"/>
    <!--<origin xyz="0.033 0 0.095" rpy="0 0 0" />-->
    <origin rpy="0 0 0" xyz="0.033 0 0.095"/>
    <axis xyz="0 -1.0 0"/>
    <limit effort="2" lower="-0.349065850399" upper="0.349065850399" velocity="2.0"/>
    <dynamics damping="0.1"/>
  </joint>
  <gazebo reference="rh_FFJ4">
    <provideFeedback>1</provideFeedback>
    <implicitSpringDamper>1</implicitSpringDamper>
  </gazebo>
  <transmission name="rh_ffknuckle_transmission">
    <type>sr_mechanism_model/SimpleTransmission</type>
    <actuator name="rh_FFJ4">
      <mechanicalReduction>1</mechanicalReduction>
    </actuator>
    <joint name="rh_FFJ4">
      <hardwareInterface>EffortJointInterface</hardwareInterface>
      <hardwareInterface>PositionJointInterface</hardwareInterface>
    </joint>
  </transmission>
  <!-- prefix can be anything but usually is "r_" or  "l_" for right and left hands distinction -->
  <gazebo reference="rh_ffknuckle">
    <sensor name="rh_ffknuckle_contact" type="contact">
      <always_on>1</always_on>
      <update_rate>1000.0</update_rate>
      <contact>
        <collision>rh_ffknuckle_collision</collision>
        <topic>rh_ffknuckle_collision</topic>
      </contact>
      <plugin filename="libgazebo_ros_bumper.so" name="rh_ffknuckle_gazebo_ros_bumper_controller">
        <alwaysOn>true</alwaysOn>
        <frameName>rh_ffknuckle</frameName>
        <updateRate>100.0</updateRate>
        <bumperTopicName>contacts/rh_ff/knuckle</bumperTopicName>
      </plugin>
    </sensor>
    <material>Gazebo/Grey</material>
  </gazebo>
  <link name="rh_ffproximal">
    <inertial>
      <mass value="0.030"/>
      <origin xyz="0 0 0.0225"/>
      <inertia ixx="0.0000098" ixy="0.0" ixz="0.0" iyy="0.00001" iyz="0.0" izz="0.0000018"/>
    </inertial>
    <visual>
      <origin rpy="0 0 0" xyz="0 0 0"/>
      <geometry name="rh_ffproximal_visual">
        <mesh filename="package://sr_description/hand/model/F3.dae" scale="0.001 0.001 0.001"/>
      </geometry>
      <material name="Grey"/>
    </visual>
    <collision>
      <origin rpy="0 0 0" xyz="0 0 0.025"/>
      <geometry name="rh_ffproximal_collision_geom">
        <cylinder length="0.040" radius="0.007"/>
      </geometry>
    </collision>
  </link>
  <joint name="rh_FFJ3" type="revolute">
    <parent link="rh_ffknuckle"/>
    <child link="rh_ffproximal"/>
    <origin rpy="0 0 0" xyz="0 0 0"/>
    <axis xyz="1 0 0"/>
    <limit effort="2" lower="0" upper="1.57079632679" velocity="2.0"/>
    <dynamics damping="0.1"/>
  </joint>
  <gazebo reference="rh_FFJ3">
    <provideFeedback>1</provideFeedback>
    <implicitSpringDamper>1</implicitSpringDamper>
  </gazebo>
  <transmission name="rh_ffproximal_transmission">
    <type>sr_mechanism_model/SimpleTransmission</type>
    <actuator name="rh_FFJ3">
      <mechanicalReduction>1</mechanicalReduction>
    </actuator>
    <joint name="rh_FFJ3">
      <hardwareInterface>EffortJointInterface</hardwareInterface>
      <hardwareInterface>PositionJointInterface</hardwareInterface>
    </joint>
  </transmission>
  <!-- prefix can be anything but usually is "r_" or  "l_" for right and left hands distinction -->
  <gazebo reference="rh_ffproximal">
    <sensor name="rh_ffproximal_contact" type="contact">
      <always_on>1</always_on>
      <update_rate>1000.0</update_rate>
      <contact>
        <collision>rh_ffproximal_collision</collision>
        <topic>rh_ffproximal_collision</topic>
      </contact>
      <plugin filename="libgazebo_ros_bumper.so" name="rh_ffproximal_gazebo_ros_bumper_controller">
        <alwaysOn>true</alwaysOn>
        <frameName>rh_ffproximal</frameName>
        <updateRate>100.0</updateRate>
        <bumperTopicName>contacts/rh_ff/proximal</bumperTopicName>
      </plugin>
    </sensor>
    <selfCollide>true</selfCollide>
  </gazebo>
  <link name="rh_ffmiddle">
    <inertial>
      <origin rpy="0 0 0" xyz="0 0 0.0125"/>
      <mass value="0.017"/>
      <inertia ixx="0.0000026" ixy="0.0" ixz="0.0" iyy="0.0000027" iyz="0.0" izz="0.00000087"/>
    </inertial>
    <visual>
      <origin rpy="0 0 0" xyz="0 0 0"/>
      <geometry name="rh_ffmiddle_visual">
        <mesh filename="package://sr_description/hand/model/F2.dae" scale="0.001 0.001 0.001"/>
      </geometry>
      <material name="Grey"/>
    </visual>
    <collision>
      <origin rpy="0 0 0" xyz="0 0 0.0125"/>
      <geometry name="rh_ffmiddle_collision_geom">
        <cylinder length="0.025" radius="0.007"/>
      </geometry>
    </collision>
    <collision>
      <origin rpy="0 0 0" xyz="0 0 0.0"/>
      <geometry>
        <sphere radius="0.007"/>
      </geometry>
    </collision>
    <collision>
      <origin rpy="0 0 0" xyz="0 0 0.025"/>
      <geometry>
        <sphere radius="0.007"/>
      </geometry>
    </collision>
  </link>
  <joint name="rh_FFJ2" type="revolute">
    <parent link="rh_ffproximal"/>
    <child link="rh_ffmiddle"/>
    <origin rpy="0 0 0" xyz="0 0 0.045"/>
    <axis xyz="1 0 0"/>
    <limit effort="2" lower="0" upper="1.57079632679" velocity="2.0"/>
    <dynamics damping="0.1"/>
  </joint>
  <gazebo reference="rh_FFJ2">
    <provideFeedback>1</provideFeedback>
    <implicitSpringDamper>1</implicitSpringDamper>
  </gazebo>
  <transmission name="rh_ffmiddle_transmission">
    <type>sr_mechanism_model/J0Transmission</type>
    <actuator name="rh_FFJ0">
      <mechanicalReduction>1</mechanicalReduction>
    </actuator>
    <joint name="rh_FFJ1">
      <hardwareInterface>EffortJointInterface</hardwareInterface>
      <hardwareInterface>PositionJointInterface</hardwareInterface>
    </joint>
    <secondJoint name="rh_FFJ2"/>
  </transmission>
  <!-- prefix can be anything but usually is "r_" or  "l_" for right and left hands distinction -->
  <gazebo reference="rh_ffmiddle">
    <sensor name="rh_ffmiddle_contact" type="contact">
      <always_on>1</always_on>
      <update_rate>1000.0</update_rate>
      <contact>
        <collision>rh_ffmiddle_collision</collision>
        <topic>rh_ffmiddle_collision</topic>
      </contact>
      <plugin filename="libgazebo_ros_bumper.so" name="rh_ffproximal_gazebo_ros_bumper_controller">
        <alwaysOn>true</alwaysOn>
        <frameName>rh_ffmiddle</frameName>
        <updateRate>100.0</updateRate>
        <bumperTopicName>contacts/rh_ff/middle</bumperTopicName>
      </plugin>
    </sensor>
    <selfCollide>true</selfCollide>
  </gazebo>
  <link name="rh_ffdistal">
    <inertial>
      <mass value="0.012"/>
      <origin xyz="0 0 0.012"/>
      <inertia ixx="0.00000094" ixy="0.0" ixz="0.0" iyy="0.0000011" iyz="0.0" izz="0.00000053"/>
    </inertial>
    <visual>
      <origin rpy="0 0 0" xyz="0 0 0"/>
      <geometry name="rh_ffdistal_visual">
        <!-- Standard distal  -->
        <mesh filename="package://sr_description/hand/model/F1.dae" scale="0.001 0.001 0.001"/>
      </geometry>
      <material name="Grey"/>
    </visual>
    <collision>
      <origin rpy="0 0 0" xyz="0 0 0"/>
      <geometry name="rh_ffdistal_collision_geom">
        <!-- Standard distal  -->
        <mesh filename="package://sr_description/hand/model/F1.dae" scale="0.001 0.001 0.001"/>
      </geometry>
    </collision>
  </link>
  <joint name="rh_FFJ1" type="revolute">
    <parent link="rh_ffmiddle"/>
    <child link="rh_ffdistal"/>
    <origin rpy="0 0 0" xyz="0 0 0.025"/>
    <axis xyz="1 0 0"/>
    <!-- standard distal joint -->
    <limit effort="2" lower="0" upper="1.57079632679" velocity="2.0"/>
    <dynamics damping="0.1"/>
  </joint>
  <gazebo reference="rh_FFJ1">
    <provideFeedback>1</provideFeedback>
    <implicitSpringDamper>1</implicitSpringDamper>
  </gazebo>
  <link name="rh_fftip">
    <inertial>
      <mass value="0.001"/>
      <inertia ixx="0.0" ixy="0.0" ixz="0.0" iyy="0.0" iyz="0.0" izz="0.0"/>
    </inertial>
  </link>
  <joint name="rh_FFtip" type="fixed">
    <parent link="rh_ffdistal"/>
    <child link="rh_fftip"/>
    <origin rpy="0 0 0" xyz="0 0 0.026"/>
  </joint>
  <!-- prefix can be anything but usually is "r_" or  "l_" for right and left hands distinction -->
  <gazebo reference="rh_ffdistal">
    <sensor name="rh_ffdistal_contact" type="contact">
      <always_on>1</always_on>
      <update_rate>1000.0</update_rate>
      <contact>
        <collision>rh_ffdistal_collision</collision>
        <topic>rh_ffdistal_collision</topic>
      </contact>
      <plugin filename="libgazebo_ros_bumper.so" name="rh_ffdistal_gazebo_ros_bumper_controller">
        <alwaysOn>true</alwaysOn>
        <frameName>rh_ffdistal</frameName>
        <updateRate>100.0</updateRate>
        <bumperTopicName>contacts/rh_ff/distal</bumperTopicName>
      </plugin>
    </sensor>
    <mu1 value="500.0"/>
    <mu2 value="500.0"/>
    <kp value="10000000.0"/>
    <kd value="1.0"/>
    <selfCollide>true</selfCollide>
  </gazebo>
  <link name="rh_mfknuckle">
    <inertial>
      <origin rpy="0 0 0" xyz="0 0 0"/>
      <mass value="0.008"/>
      <inertia ixx="0.00000026" ixy="0.0" ixz="0.0" iyy="0.00000026" iyz="0.0" izz="0.00000032"/>
    </inertial>
    <visual>
      <origin rpy="0 0 0" xyz="0 0 0.0005"/>
      <geometry name="rh_mfknuckle_visual">
        <mesh filename="package://sr_description/hand/model/knuckle.dae" scale="0.001 0.001 0.001"/>
      </geometry>
      <material name="LightGrey"/>
    </visual>
    <collision>
      <origin rpy="0 1.5708 0" xyz="0 0 0"/>
      <geometry name="rh_mfknuckle_collision_geom">
        <cylinder length="0.014" radius="0.007"/>
      </geometry>
    </collision>
  </link>
  <joint name="rh_MFJ4" type="revolute">
    <parent link="rh_palm"/>
    <child link="rh_mfknuckle"/>
    <!--<origin xyz="0.033 0 0.095" rpy="0 0 0" />-->
    <origin rpy="0 0 0" xyz="0.011 0 0.099"/>
    <axis xyz="0 -1.0 0"/>
    <limit effort="2" lower="-0.349065850399" upper="0.349065850399" velocity="2.0"/>
    <dynamics damping="0.1"/>
  </joint>
  <gazebo reference="rh_MFJ4">
    <provideFeedback>1</provideFeedback>
    <implicitSpringDamper>1</implicitSpringDamper>
  </gazebo>
  <transmission name="rh_mfknuckle_transmission">
    <type>sr_mechanism_model/SimpleTransmission</type>
    <actuator name="rh_MFJ4">
      <mechanicalReduction>1</mechanicalReduction>
    </actuator>
    <joint name="rh_MFJ4">
      <hardwareInterface>EffortJointInterface</hardwareInterface>
      <hardwareInterface>PositionJointInterface</hardwareInterface>
    </joint>
  </transmission>
  <!-- prefix can be anything but usually is "r_" or  "l_" for right and left hands distinction -->
  <gazebo reference="rh_mfknuckle">
    <sensor name="rh_mfknuckle_contact" type="contact">
      <always_on>1</always_on>
      <update_rate>1000.0</update_rate>
      <contact>
        <collision>rh_mfknuckle_collision</collision>
        <topic>rh_mfknuckle_collision</topic>
      </contact>
      <plugin filename="libgazebo_ros_bumper.so" name="rh_mfknuckle_gazebo_ros_bumper_controller">
        <alwaysOn>true</alwaysOn>
        <frameName>rh_mfknuckle</frameName>
        <updateRate>100.0</updateRate>
        <bumperTopicName>contacts/rh_mf/knuckle</bumperTopicName>
      </plugin>
    </sensor>
    <material>Gazebo/Grey</material>
  </gazebo>
  <link name="rh_mfproximal">
    <inertial>
      <mass value="0.030"/>
      <origin xyz="0 0 0.0225"/>
      <inertia ixx="0.0000098" ixy="0.0" ixz="0.0" iyy="0.00001" iyz="0.0" izz="0.0000018"/>
    </inertial>
    <visual>
      <origin rpy="0 0 0" xyz="0 0 0"/>
      <geometry name="rh_mfproximal_visual">
        <mesh filename="package://sr_description/hand/model/F3.dae" scale="0.001 0.001 0.001"/>
      </geometry>
      <material name="Grey"/>
    </visual>
    <collision>
      <origin rpy="0 0 0" xyz="0 0 0.025"/>
      <geometry name="rh_mfproximal_collision_geom">
        <cylinder length="0.040" radius="0.007"/>
      </geometry>
    </collision>
  </link>
  <joint name="rh_MFJ3" type="revolute">
    <parent link="rh_mfknuckle"/>
    <child link="rh_mfproximal"/>
    <origin rpy="0 0 0" xyz="0 0 0"/>
    <axis xyz="1 0 0"/>
    <limit effort="2" lower="0" upper="1.57079632679" velocity="2.0"/>
    <dynamics damping="0.1"/>
  </joint>
  <gazebo reference="rh_MFJ3">
    <provideFeedback>1</provideFeedback>
    <implicitSpringDamper>1</implicitSpringDamper>
  </gazebo>
  <transmission name="rh_mfproximal_transmission">
    <type>sr_mechanism_model/SimpleTransmission</type>
    <actuator name="rh_MFJ3">
      <mechanicalReduction>1</mechanicalReduction>
    </actuator>
    <joint name="rh_MFJ3">
      <hardwareInterface>EffortJointInterface</hardwareInterface>
      <hardwareInterface>PositionJointInterface</hardwareInterface>
    </joint>
  </transmission>
  <!-- prefix can be anything but usually is "r_" or  "l_" for right and left hands distinction -->
  <gazebo reference="rh_mfproximal">
    <sensor name="rh_mfproximal_contact" type="contact">
      <always_on>1</always_on>
      <update_rate>1000.0</update_rate>
      <contact>
        <collision>rh_mfproximal_collision</collision>
        <topic>rh_mfproximal_collision</topic>
      </contact>
      <plugin filename="libgazebo_ros_bumper.so" name="rh_mfproximal_gazebo_ros_bumper_controller">
        <alwaysOn>true</alwaysOn>
        <frameName>rh_mfproximal</frameName>
        <updateRate>100.0</updateRate>
        <bumperTopicName>contacts/rh_mf/proximal</bumperTopicName>
      </plugin>
    </sensor>
    <selfCollide>true</selfCollide>
  </gazebo>
  <link name="rh_mfmiddle">
    <inertial>
      <origin rpy="0 0 0" xyz="0 0 0.0125"/>
      <mass value="0.017"/>
      <inertia ixx="0.0000026" ixy="0.0" ixz="0.0" iyy="0.0000027" iyz="0.0" izz="0.00000087"/>
    </inertial>
    <visual>
      <origin rpy="0 0 0" xyz="0 0 0"/>
      <geometry name="rh_mfmiddle_visual">
        <mesh filename="package://sr_description/hand/model/F2.dae" scale="0.001 0.001 0.001"/>
      </geometry>
      <material name="Grey"/>
    </visual>
    <collision>
      <origin rpy="0 0 0" xyz="0 0 0.0125"/>
      <geometry name="rh_mfmiddle_collision_geom">
        <cylinder length="0.025" radius="0.007"/>
      </geometry>
    </collision>
    <collision>
      <origin rpy="0 0 0" xyz="0 0 0.0"/>
      <geometry>
        <sphere radius="0.007"/>
      </geometry>
    </collision>
    <collision>
      <origin rpy="0 0 0" xyz="0 0 0.025"/>
      <geometry>
        <sphere radius="0.007"/>
      </geometry>
    </collision>
  </link>
  <joint name="rh_MFJ2" type="revolute">
    <parent link="rh_mfproximal"/>
    <child link="rh_mfmiddle"/>
    <origin rpy="0 0 0" xyz="0 0 0.045"/>
    <axis xyz="1 0 0"/>
    <limit effort="2" lower="0" upper="1.57079632679" velocity="2.0"/>
    <dynamics damping="0.1"/>
  </joint>
  <gazebo reference="rh_MFJ2">
    <provideFeedback>1</provideFeedback>
    <implicitSpringDamper>1</implicitSpringDamper>
  </gazebo>
  <transmission name="rh_mfmiddle_transmission">
    <type>sr_mechanism_model/J0Transmission</type>
    <actuator name="rh_MFJ0">
      <mechanicalReduction>1</mechanicalReduction>
    </actuator>
    <joint name="rh_MFJ1">
      <hardwareInterface>EffortJointInterface</hardwareInterface>
      <hardwareInterface>PositionJointInterface</hardwareInterface>
    </joint>
    <secondJoint name="rh_MFJ2"/>
  </transmission>
  <!-- prefix can be anything but usually is "r_" or  "l_" for right and left hands distinction -->
  <gazebo reference="rh_mfmiddle">
    <sensor name="rh_mfmiddle_contact" type="contact">
      <always_on>1</always_on>
      <update_rate>1000.0</update_rate>
      <contact>
        <collision>rh_mfmiddle_collision</collision>
        <topic>rh_mfmiddle_collision</topic>
      </contact>
      <plugin filename="libgazebo_ros_bumper.so" name="rh_mfproximal_gazebo_ros_bumper_controller">
        <alwaysOn>true</alwaysOn>
        <frameName>rh_mfmiddle</frameName>
        <updateRate>100.0</updateRate>
        <bumperTopicName>contacts/rh_mf/middle</bumperTopicName>
      </plugin>
    </sensor>
    <selfCollide>true</selfCollide>
  </gazebo>
  <link name="rh_mfdistal">
    <inertial>
      <mass value="0.012"/>
      <origin xyz="0 0 0.012"/>
      <inertia ixx="0.00000094" ixy="0.0" ixz="0.0" iyy="0.0000011" iyz="0.0" izz="0.00000053"/>
    </inertial>
    <visual>
      <origin rpy="0 0 0" xyz="0 0 0"/>
      <geometry name="rh_mfdistal_visual">
        <!-- Standard distal  -->
        <mesh filename="package://sr_description/hand/model/F1.dae" scale="0.001 0.001 0.001"/>
      </geometry>
      <material name="Grey"/>
    </visual>
    <collision>
      <origin rpy="0 0 0" xyz="0 0 0"/>
      <geometry name="rh_mfdistal_collision_geom">
        <!-- Standard distal  -->
        <mesh filename="package://sr_description/hand/model/F1.dae" scale="0.001 0.001 0.001"/>
      </geometry>
    </collision>
  </link>
  <joint name="rh_MFJ1" type="revolute">
    <parent link="rh_mfmiddle"/>
    <child link="rh_mfdistal"/>
    <origin rpy="0 0 0" xyz="0 0 0.025"/>
    <axis xyz="1 0 0"/>
    <!-- standard distal joint -->
    <limit effort="2" lower="0" upper="1.57079632679" velocity="2.0"/>
    <dynamics damping="0.1"/>
  </joint>
  <gazebo reference="rh_MFJ1">
    <provideFeedback>1</provideFeedback>
    <implicitSpringDamper>1</implicitSpringDamper>
  </gazebo>
  <link name="rh_mftip">
    <inertial>
      <mass value="0.001"/>
      <inertia ixx="0.0" ixy="0.0" ixz="0.0" iyy="0.0" iyz="0.0" izz="0.0"/>
    </inertial>
  </link>
  <joint name="rh_MFtip" type="fixed">
    <parent link="rh_mfdistal"/>
    <child link="rh_mftip"/>
    <origin rpy="0 0 0" xyz="0 0 0.026"/>
  </joint>
  <!-- prefix can be anything but usually is "r_" or  "l_" for right and left hands distinction -->
  <gazebo reference="rh_mfdistal">
    <sensor name="rh_mfdistal_contact" type="contact">
      <always_on>1</always_on>
      <update_rate>1000.0</update_rate>
      <contact>
        <collision>rh_mfdistal_collision</collision>
        <topic>rh_mfdistal_collision</topic>
      </contact>
      <plugin filename="libgazebo_ros_bumper.so" name="rh_mfdistal_gazebo_ros_bumper_controller">
        <alwaysOn>true</alwaysOn>
        <frameName>rh_mfdistal</frameName>
        <updateRate>100.0</updateRate>
        <bumperTopicName>contacts/rh_mf/distal</bumperTopicName>
      </plugin>
    </sensor>
    <mu1 value="500.0"/>
    <mu2 value="500.0"/>
    <kp value="10000000.0"/>
    <kd value="1.0"/>
    <selfCollide>true</selfCollide>
  </gazebo>
  <link name="rh_rfknuckle">
    <inertial>
      <origin rpy="0 0 0" xyz="0 0 0"/>
      <mass value="0.008"/>
      <inertia ixx="0.00000026" ixy="0.0" ixz="0.0" iyy="0.00000026" iyz="0.0" izz="0.00000032"/>
    </inertial>
    <visual>
      <origin rpy="0 0 0" xyz="0 0 0.0005"/>
      <geometry name="rh_rfknuckle_visual">
        <mesh filename="package://sr_description/hand/model/knuckle.dae" scale="0.001 0.001 0.001"/>
      </geometry>
      <material name="LightGrey"/>
    </visual>
    <collision>
      <origin rpy="0 1.5708 0" xyz="0 0 0"/>
      <geometry name="rh_rfknuckle_collision_geom">
        <cylinder length="0.014" radius="0.007"/>
      </geometry>
    </collision>
  </link>
  <joint name="rh_RFJ4" type="revolute">
    <parent link="rh_palm"/>
    <child link="rh_rfknuckle"/>
    <!--<origin xyz="0.033 0 0.095" rpy="0 0 0" />-->
    <origin rpy="0 0 0" xyz="-0.011 0 0.095"/>
    <axis xyz="0 1.0 0"/>
    <limit effort="2" lower="-0.349065850399" upper="0.349065850399" velocity="2.0"/>
    <dynamics damping="0.1"/>
  </joint>
  <gazebo reference="rh_RFJ4">
    <provideFeedback>1</provideFeedback>
    <implicitSpringDamper>1</implicitSpringDamper>
  </gazebo>
  <transmission name="rh_rfknuckle_transmission">
    <type>sr_mechanism_model/SimpleTransmission</type>
    <actuator name="rh_RFJ4">
      <mechanicalReduction>1</mechanicalReduction>
    </actuator>
    <joint name="rh_RFJ4">
      <hardwareInterface>EffortJointInterface</hardwareInterface>
      <hardwareInterface>PositionJointInterface</hardwareInterface>
    </joint>
  </transmission>
  <!-- prefix can be anything but usually is "r_" or  "l_" for right and left hands distinction -->
  <gazebo reference="rh_rfknuckle">
    <sensor name="rh_rfknuckle_contact" type="contact">
      <always_on>1</always_on>
      <update_rate>1000.0</update_rate>
      <contact>
        <collision>rh_rfknuckle_collision</collision>
        <topic>rh_rfknuckle_collision</topic>
      </contact>
      <plugin filename="libgazebo_ros_bumper.so" name="rh_rfknuckle_gazebo_ros_bumper_controller">
        <alwaysOn>true</alwaysOn>
        <frameName>rh_rfknuckle</frameName>
        <updateRate>100.0</updateRate>
        <bumperTopicName>contacts/rh_rf/knuckle</bumperTopicName>
      </plugin>
    </sensor>
    <material>Gazebo/Grey</material>
  </gazebo>
  <link name="rh_rfproximal">
    <inertial>
      <mass value="0.030"/>
      <origin xyz="0 0 0.0225"/>
      <inertia ixx="0.0000098" ixy="0.0" ixz="0.0" iyy="0.00001" iyz="0.0" izz="0.0000018"/>
    </inertial>
    <visual>
      <origin rpy="0 0 0" xyz="0 0 0"/>
      <geometry name="rh_rfproximal_visual">
        <mesh filename="package://sr_description/hand/model/F3.dae" scale="0.001 0.001 0.001"/>
      </geometry>
      <material name="Grey"/>
    </visual>
    <collision>
      <origin rpy="0 0 0" xyz="0 0 0.025"/>
      <geometry name="rh_rfproximal_collision_geom">
        <cylinder length="0.040" radius="0.007"/>
      </geometry>
    </collision>
  </link>
  <joint name="rh_RFJ3" type="revolute">
    <parent link="rh_rfknuckle"/>
    <child link="rh_rfproximal"/>
    <origin rpy="0 0 0" xyz="0 0 0"/>
    <axis xyz="1 0 0"/>
    <limit effort="2" lower="0" upper="1.57079632679" velocity="2.0"/>
    <dynamics damping="0.1"/>
  </joint>
  <gazebo reference="rh_RFJ3">
    <provideFeedback>1</provideFeedback>
    <implicitSpringDamper>1</implicitSpringDamper>
  </gazebo>
  <transmission name="rh_rfproximal_transmission">
    <type>sr_mechanism_model/SimpleTransmission</type>
    <actuator name="rh_RFJ3">
      <mechanicalReduction>1</mechanicalReduction>
    </actuator>
    <joint name="rh_RFJ3">
      <hardwareInterface>EffortJointInterface</hardwareInterface>
      <hardwareInterface>PositionJointInterface</hardwareInterface>
    </joint>
  </transmission>
  <!-- prefix can be anything but usually is "r_" or  "l_" for right and left hands distinction -->
  <gazebo reference="rh_rfproximal">
    <sensor name="rh_rfproximal_contact" type="contact">
      <always_on>1</always_on>
      <update_rate>1000.0</update_rate>
      <contact>
        <collision>rh_rfproximal_collision</collision>
        <topic>rh_rfproximal_collision</topic>
      </contact>
      <plugin filename="libgazebo_ros_bumper.so" name="rh_rfproximal_gazebo_ros_bumper_controller">
        <alwaysOn>true</alwaysOn>
        <frameName>rh_rfproximal</frameName>
        <updateRate>100.0</updateRate>
        <bumperTopicName>contacts/rh_rf/proximal</bumperTopicName>
      </plugin>
    </sensor>
    <selfCollide>true</selfCollide>
  </gazebo>
  <link name="rh_rfmiddle">
    <inertial>
      <origin rpy="0 0 0" xyz="0 0 0.0125"/>
      <mass value="0.017"/>
      <inertia ixx="0.0000026" ixy="0.0" ixz="0.0" iyy="0.0000027" iyz="0.0" izz="0.00000087"/>
    </inertial>
    <visual>
      <origin rpy="0 0 0" xyz="0 0 0"/>
      <geometry name="rh_rfmiddle_visual">
        <mesh filename="package://sr_description/hand/model/F2.dae" scale="0.001 0.001 0.001"/>
      </geometry>
      <material name="Grey"/>
    </visual>
    <collision>
      <origin rpy="0 0 0" xyz="0 0 0.0125"/>
      <geometry name="rh_rfmiddle_collision_geom">
        <cylinder length="0.025" radius="0.007"/>
      </geometry>
    </collision>
    <collision>
      <origin rpy="0 0 0" xyz="0 0 0.0"/>
      <geometry>
        <sphere radius="0.007"/>
      </geometry>
    </collision>
    <collision>
      <origin rpy="0 0 0" xyz="0 0 0.025"/>
      <geometry>
        <sphere radius="0.007"/>
      </geometry>
    </collision>
  </link>
  <joint name="rh_RFJ2" type="revolute">
    <parent link="rh_rfproximal"/>
    <child link="rh_rfmiddle"/>
    <origin rpy="0 0 0" xyz="0 0 0.045"/>
    <axis xyz="1 0 0"/>
    <limit effort="2" lower="0" upper="1.57079632679" velocity="2.0"/>
    <dynamics damping="0.1"/>
  </joint>
  <gazebo reference="rh_RFJ2">
    <provideFeedback>1</provideFeedback>
    <implicitSpringDamper>1</implicitSpringDamper>
  </gazebo>
  <transmission name="rh_rfmiddle_transmission">
    <type>sr_mechanism_model/J0Transmission</type>
    <actuator name="rh_RFJ0">
      <mechanicalReduction>1</mechanicalReduction>
    </actuator>
    <joint name="rh_RFJ1">
      <hardwareInterface>EffortJointInterface</hardwareInterface>
      <hardwareInterface>PositionJointInterface</hardwareInterface>
    </joint>
    <secondJoint name="rh_RFJ2"/>
  </transmission>
  <!-- prefix can be anything but usually is "r_" or  "l_" for right and left hands distinction -->
  <gazebo reference="rh_rfmiddle">
    <sensor name="rh_rfmiddle_contact" type="contact">
      <always_on>1</always_on>
      <update_rate>1000.0</update_rate>
      <contact>
        <collision>rh_rfmiddle_collision</collision>
        <topic>rh_rfmiddle_collision</topic>
      </contact>
      <plugin filename="libgazebo_ros_bumper.so" name="rh_rfproximal_gazebo_ros_bumper_controller">
        <alwaysOn>true</alwaysOn>
        <frameName>rh_rfmiddle</frameName>
        <updateRate>100.0</updateRate>
        <bumperTopicName>contacts/rh_rf/middle</bumperTopicName>
      </plugin>
    </sensor>
    <selfCollide>true</selfCollide>
  </gazebo>
  <link name="rh_rfdistal">
    <inertial>
      <mass value="0.012"/>
      <origin xyz="0 0 0.012"/>
      <inertia ixx="0.00000094" ixy="0.0" ixz="0.0" iyy="0.0000011" iyz="0.0" izz="0.00000053"/>
    </inertial>
    <visual>
      <origin rpy="0 0 0" xyz="0 0 0"/>
      <geometry name="rh_rfdistal_visual">
        <!-- Standard distal  -->
        <mesh filename="package://sr_description/hand/model/F1.dae" scale="0.001 0.001 0.001"/>
      </geometry>
      <material name="Grey"/>
    </visual>
    <collision>
      <origin rpy="0 0 0" xyz="0 0 0"/>
      <geometry name="rh_rfdistal_collision_geom">
        <!-- Standard distal  -->
        <mesh filename="package://sr_description/hand/model/F1.dae" scale="0.001 0.001 0.001"/>
      </geometry>
    </collision>
  </link>
  <joint name="rh_RFJ1" type="revolute">
    <parent link="rh_rfmiddle"/>
    <child link="rh_rfdistal"/>
    <origin rpy="0 0 0" xyz="0 0 0.025"/>
    <axis xyz="1 0 0"/>
    <!-- standard distal joint -->
    <limit effort="2" lower="0" upper="1.57079632679" velocity="2.0"/>
    <dynamics damping="0.1"/>
  </joint>
  <gazebo reference="rh_RFJ1">
    <provideFeedback>1</provideFeedback>
    <implicitSpringDamper>1</implicitSpringDamper>
  </gazebo>
  <link name="rh_rftip">
    <inertial>
      <mass value="0.001"/>
      <inertia ixx="0.0" ixy="0.0" ixz="0.0" iyy="0.0" iyz="0.0" izz="0.0"/>
    </inertial>
  </link>
  <joint name="rh_RFtip" type="fixed">
    <parent link="rh_rfdistal"/>
    <child link="rh_rftip"/>
    <origin rpy="0 0 0" xyz="0 0 0.026"/>
  </joint>
  <!-- prefix can be anything but usually is "r_" or  "l_" for right and left hands distinction -->
  <gazebo reference="rh_rfdistal">
    <sensor name="rh_rfdistal_contact" type="contact">
      <always_on>1</always_on>
      <update_rate>1000.0</update_rate>
      <contact>
        <collision>rh_rfdistal_collision</collision>
        <topic>rh_rfdistal_collision</topic>
      </contact>
      <plugin filename="libgazebo_ros_bumper.so" name="rh_rfdistal_gazebo_ros_bumper_controller">
        <alwaysOn>true</alwaysOn>
        <frameName>rh_rfdistal</frameName>
        <updateRate>100.0</updateRate>
        <bumperTopicName>contacts/rh_rf/distal</bumperTopicName>
      </plugin>
    </sensor>
    <mu1 value="500.0"/>
    <mu2 value="500.0"/>
    <kp value="10000000.0"/>
    <kd value="1.0"/>
    <selfCollide>true</selfCollide>
  </gazebo>
  <link name="rh_lfmetacarpal">
    <inertial>
      <origin rpy="0 0 0" xyz="0 0 0.04"/>
      <mass value="0.030"/>
      <inertia ixx="0.0000145" ixy="0.0" ixz="0.0" iyy="0.00001638" iyz="0.0" izz="0.000004272"/>
    </inertial>
    <visual>
      <origin rpy="0 0 0" xyz="0 0 0"/>
      <geometry name="rh_lfmetacarpal_visual">
        <mesh filename="package://sr_description/hand/model/lfmetacarpal.dae" scale="0.001 0.001 0.001"/>
      </geometry>
      <material name="Grey"/>
    </visual>
    <collision>
      <origin rpy="0 0 0" xyz="0 0 0.038"/>
      <geometry name="rh_lfmetacarpal_collision_geom">
        <box size="0.018 0.024 0.040"/>
      </geometry>
    </collision>
  </link>
  <joint name="rh_LFJ5" type="revolute">
    <parent link="rh_palm"/>
    <child link="rh_lfmetacarpal"/>
    <origin rpy="0 0 0" xyz="-0.033 0 0.02071"/>
    <axis xyz="0.573576436 0 0.819152044"/>
    <limit effort="2" lower="0" upper="0.785398163397" velocity="2.0"/>
    <dynamics damping="0.1"/>
  </joint>
  <gazebo reference="rh_LFJ5">
    <provideFeedback>1</provideFeedback>
    <implicitSpringDamper>1</implicitSpringDamper>
  </gazebo>
  <transmission name="rh_lfmetacarpal_transmission">
    <type>sr_mechanism_model/SimpleTransmission</type>
    <actuator name="rh_LFJ5">
      <mechanicalReduction>1</mechanicalReduction>
    </actuator>
    <joint name="rh_LFJ5">
      <hardwareInterface>EffortJointInterface</hardwareInterface>
      <hardwareInterface>PositionJointInterface</hardwareInterface>
    </joint>
  </transmission>
  <!-- prefix can be anything but usually is "r_" or  "l_" for right and left hands distinction -->
  <gazebo reference="rh_lfmetacarpal">
    <sensor name="rh_lfmetacarpal_contact" type="contact">
      <always_on>1</always_on>
      <update_rate>1000.0</update_rate>
      <contact>
        <collision>rh_lfmetacarpal_collision</collision>
        <topic>rh_lfmetacarpal_collision</topic>
      </contact>
      <plugin filename="libgazebo_ros_bumper.so" name="rh_lfmetacarpal_gazebo_ros_bumper_controller">
        <alwaysOn>true</alwaysOn>
        <frameName>rh_lfmetacarpal</frameName>
        <updateRate>100.0</updateRate>
        <bumperTopicName>contacts/rh_lf/metacarpal</bumperTopicName>
      </plugin>
    </sensor>
    <selfCollide>true</selfCollide>
  </gazebo>
  <link name="rh_lfknuckle">
    <inertial>
      <origin rpy="0 0 0" xyz="0 0 0"/>
      <mass value="0.008"/>
      <inertia ixx="0.00000026" ixy="0.0" ixz="0.0" iyy="0.00000026" iyz="0.0" izz="0.00000032"/>
    </inertial>
    <visual>
      <origin rpy="0 0 0" xyz="0 0 0.0005"/>
      <geometry name="rh_lfknuckle_visual">
        <mesh filename="package://sr_description/hand/model/knuckle.dae" scale="0.001 0.001 0.001"/>
      </geometry>
      <material name="LightGrey"/>
    </visual>
    <collision>
      <origin rpy="0 1.5708 0" xyz="0 0 0"/>
      <geometry name="rh_lfknuckle_collision_geom">
        <cylinder length="0.014" radius="0.007"/>
      </geometry>
    </collision>
  </link>
  <joint name="rh_LFJ4" type="revolute">
    <parent link="rh_lfmetacarpal"/>
    <child link="rh_lfknuckle"/>
    <!--<origin xyz="0.033 0 0.095" rpy="0 0 0" />-->
    <origin rpy="0 0 0" xyz="0 0 0.06579"/>
    <axis xyz="0 1.0 0"/>
    <limit effort="2" lower="-0.349065850399" upper="0.349065850399" velocity="2.0"/>
    <dynamics damping="0.1"/>
  </joint>
  <gazebo reference="rh_LFJ4">
    <provideFeedback>1</provideFeedback>
    <implicitSpringDamper>1</implicitSpringDamper>
  </gazebo>
  <transmission name="rh_lfknuckle_transmission">
    <type>sr_mechanism_model/SimpleTransmission</type>
    <actuator name="rh_LFJ4">
      <mechanicalReduction>1</mechanicalReduction>
    </actuator>
    <joint name="rh_LFJ4">
      <hardwareInterface>EffortJointInterface</hardwareInterface>
      <hardwareInterface>PositionJointInterface</hardwareInterface>
    </joint>
  </transmission>
  <!-- prefix can be anything but usually is "r_" or  "l_" for right and left hands distinction -->
  <gazebo reference="rh_lfknuckle">
    <sensor name="rh_lfknuckle_contact" type="contact">
      <always_on>1</always_on>
      <update_rate>1000.0</update_rate>
      <contact>
        <collision>rh_lfknuckle_collision</collision>
        <topic>rh_lfknuckle_collision</topic>
      </contact>
      <plugin filename="libgazebo_ros_bumper.so" name="rh_lfknuckle_gazebo_ros_bumper_controller">
        <alwaysOn>true</alwaysOn>
        <frameName>rh_lfknuckle</frameName>
        <updateRate>100.0</updateRate>
        <bumperTopicName>contacts/rh_lf/knuckle</bumperTopicName>
      </plugin>
    </sensor>
    <material>Gazebo/Grey</material>
  </gazebo>
  <link name="rh_lfproximal">
    <inertial>
      <mass value="0.030"/>
      <origin xyz="0 0 0.0225"/>
      <inertia ixx="0.0000098" ixy="0.0" ixz="0.0" iyy="0.00001" iyz="0.0" izz="0.0000018"/>
    </inertial>
    <visual>
      <origin rpy="0 0 0" xyz="0 0 0"/>
      <geometry name="rh_lfproximal_visual">
        <mesh filename="package://sr_description/hand/model/F3.dae" scale="0.001 0.001 0.001"/>
      </geometry>
      <material name="Grey"/>
    </visual>
    <collision>
      <origin rpy="0 0 0" xyz="0 0 0.025"/>
      <geometry name="rh_lfproximal_collision_geom">
        <cylinder length="0.040" radius="0.007"/>
      </geometry>
    </collision>
  </link>
  <joint name="rh_LFJ3" type="revolute">
    <parent link="rh_lfknuckle"/>
    <child link="rh_lfproximal"/>
    <origin rpy="0 0 0" xyz="0 0 0"/>
    <axis xyz="1 0 0"/>
    <limit effort="2" lower="0" upper="1.57079632679" velocity="2.0"/>
    <dynamics damping="0.1"/>
  </joint>
  <gazebo reference="rh_LFJ3">
    <provideFeedback>1</provideFeedback>
    <implicitSpringDamper>1</implicitSpringDamper>
  </gazebo>
  <transmission name="rh_lfproximal_transmission">
    <type>sr_mechanism_model/SimpleTransmission</type>
    <actuator name="rh_LFJ3">
      <mechanicalReduction>1</mechanicalReduction>
    </actuator>
    <joint name="rh_LFJ3">
      <hardwareInterface>EffortJointInterface</hardwareInterface>
      <hardwareInterface>PositionJointInterface</hardwareInterface>
    </joint>
  </transmission>
  <!-- prefix can be anything but usually is "r_" or  "l_" for right and left hands distinction -->
  <gazebo reference="rh_lfproximal">
    <sensor name="rh_lfproximal_contact" type="contact">
      <always_on>1</always_on>
      <update_rate>1000.0</update_rate>
      <contact>
        <collision>rh_lfproximal_collision</collision>
        <topic>rh_lfproximal_collision</topic>
      </contact>
      <plugin filename="libgazebo_ros_bumper.so" name="rh_lfproximal_gazebo_ros_bumper_controller">
        <alwaysOn>true</alwaysOn>
        <frameName>rh_lfproximal</frameName>
        <updateRate>100.0</updateRate>
        <bumperTopicName>contacts/rh_lf/proximal</bumperTopicName>
      </plugin>
    </sensor>
    <selfCollide>true</selfCollide>
  </gazebo>
  <link name="rh_lfmiddle">
    <inertial>
      <origin rpy="0 0 0" xyz="0 0 0.0125"/>
      <mass value="0.017"/>
      <inertia ixx="0.0000026" ixy="0.0" ixz="0.0" iyy="0.0000027" iyz="0.0" izz="0.00000087"/>
    </inertial>
    <visual>
      <origin rpy="0 0 0" xyz="0 0 0"/>
      <geometry name="rh_lfmiddle_visual">
        <mesh filename="package://sr_description/hand/model/F2.dae" scale="0.001 0.001 0.001"/>
      </geometry>
      <material name="Grey"/>
    </visual>
    <collision>
      <origin rpy="0 0 0" xyz="0 0 0.0125"/>
      <geometry name="rh_lfmiddle_collision_geom">
        <cylinder length="0.025" radius="0.007"/>
      </geometry>
    </collision>
    <collision>
      <origin rpy="0 0 0" xyz="0 0 0.0"/>
      <geometry>
        <sphere radius="0.007"/>
      </geometry>
    </collision>
    <collision>
      <origin rpy="0 0 0" xyz="0 0 0.025"/>
      <geometry>
        <sphere radius="0.007"/>
      </geometry>
    </collision>
  </link>
  <joint name="rh_LFJ2" type="revolute">
    <parent link="rh_lfproximal"/>
    <child link="rh_lfmiddle"/>
    <origin rpy="0 0 0" xyz="0 0 0.045"/>
    <axis xyz="1 0 0"/>
    <limit effort="2" lower="0" upper="1.57079632679" velocity="2.0"/>
    <dynamics damping="0.1"/>
  </joint>
  <gazebo reference="rh_LFJ2">
    <provideFeedback>1</provideFeedback>
    <implicitSpringDamper>1</implicitSpringDamper>
  </gazebo>
  <transmission name="rh_lfmiddle_transmission">
    <type>sr_mechanism_model/J0Transmission</type>
    <actuator name="rh_LFJ0">
      <mechanicalReduction>1</mechanicalReduction>
    </actuator>
    <joint name="rh_LFJ1">
      <hardwareInterface>EffortJointInterface</hardwareInterface>
      <hardwareInterface>PositionJointInterface</hardwareInterface>
    </joint>
    <secondJoint name="rh_LFJ2"/>
  </transmission>
  <!-- prefix can be anything but usually is "r_" or  "l_" for right and left hands distinction -->
  <gazebo reference="rh_lfmiddle">
    <sensor name="rh_lfmiddle_contact" type="contact">
      <always_on>1</always_on>
      <update_rate>1000.0</update_rate>
      <contact>
        <collision>rh_lfmiddle_collision</collision>
        <topic>rh_lfmiddle_collision</topic>
      </contact>
      <plugin filename="libgazebo_ros_bumper.so" name="rh_lfproximal_gazebo_ros_bumper_controller">
        <alwaysOn>true</alwaysOn>
        <frameName>rh_lfmiddle</frameName>
        <updateRate>100.0</updateRate>
        <bumperTopicName>contacts/rh_lf/middle</bumperTopicName>
      </plugin>
    </sensor>
    <selfCollide>true</selfCollide>
  </gazebo>
  <link name="rh_lfdistal">
    <inertial>
      <mass value="0.012"/>
      <origin xyz="0 0 0.012"/>
      <inertia ixx="0.00000094" ixy="0.0" ixz="0.0" iyy="0.0000011" iyz="0.0" izz="0.00000053"/>
    </inertial>
    <visual>
      <origin rpy="0 0 0" xyz="0 0 0"/>
      <geometry name="rh_lfdistal_visual">
        <!-- Standard distal  -->
        <mesh filename="package://sr_description/hand/model/F1.dae" scale="0.001 0.001 0.001"/>
      </geometry>
      <material name="Grey"/>
    </visual>
    <collision>
      <origin rpy="0 0 0" xyz="0 0 0"/>
      <geometry name="rh_lfdistal_collision_geom">
        <!-- Standard distal  -->
        <mesh filename="package://sr_description/hand/model/F1.dae" scale="0.001 0.001 0.001"/>
      </geometry>
    </collision>
  </link>
  <joint name="rh_LFJ1" type="revolute">
    <parent link="rh_lfmiddle"/>
    <child link="rh_lfdistal"/>
    <origin rpy="0 0 0" xyz="0 0 0.025"/>
    <axis xyz="1 0 0"/>
    <!-- standard distal joint -->
    <limit effort="2" lower="0" upper="1.57079632679" velocity="2.0"/>
    <dynamics damping="0.1"/>
  </joint>
  <gazebo reference="rh_LFJ1">
    <provideFeedback>1</provideFeedback>
    <implicitSpringDamper>1</implicitSpringDamper>
  </gazebo>
  <link name="rh_lftip">
    <inertial>
      <mass value="0.001"/>
      <inertia ixx="0.0" ixy="0.0" ixz="0.0" iyy="0.0" iyz="0.0" izz="0.0"/>
    </inertial>
  </link>
  <joint name="rh_LFtip" type="fixed">
    <parent link="rh_lfdistal"/>
    <child link="rh_lftip"/>
    <origin rpy="0 0 0" xyz="0 0 0.026"/>
  </joint>
  <!-- prefix can be anything but usually is "r_" or  "l_" for right and left hands distinction -->
  <gazebo reference="rh_lfdistal">
    <sensor name="rh_lfdistal_contact" type="contact">
      <always_on>1</always_on>
      <update_rate>1000.0</update_rate>
      <contact>
        <collision>rh_lfdistal_collision</collision>
        <topic>rh_lfdistal_collision</topic>
      </contact>
      <plugin filename="libgazebo_ros_bumper.so" name="rh_lfdistal_gazebo_ros_bumper_controller">
        <alwaysOn>true</alwaysOn>
        <frameName>rh_lfdistal</frameName>
        <updateRate>100.0</updateRate>
        <bumperTopicName>contacts/rh_lf/distal</bumperTopicName>
      </plugin>
    </sensor>
    <mu1 value="500.0"/>
    <mu2 value="500.0"/>
    <kp value="10000000.0"/>
    <kd value="1.0"/>
    <selfCollide>true</selfCollide>
  </gazebo>
  <link name="rh_thbase">
    <inertial>
      <mass value="0.010"/>
      <origin rpy="0 0 0" xyz="0 0 0"/>
      <inertia ixx="0.00000016" ixy="0.0" ixz="0.0" iyy="0.00000016" iyz="0.0" izz="0.00000016"/>
    </inertial>
    <visual>
      <origin rpy="0 0 0" xyz="0 0 0"/>
      <geometry name="rh_thbase_visual">
        <box size="0.001 0.001 0.001"/>
      </geometry>
      <material name="shadow_thbase_material">
        <color rgba="0.5 0.5 0.5 1.0"/>
      </material>
    </visual>
    <collision>
      <origin rpy="0 0 0" xyz="0 0 0"/>
      <geometry name="rh_thbase_collision_geom">
        <sphere radius="0.011"/>
      </geometry>
    </collision>
  </link>
  <joint name="rh_THJ5" type="revolute">
    <parent link="rh_palm"/>
    <child link="rh_thbase"/>
    <origin rpy="0 0.785398163397 0.0" xyz="0.034 -0.0085 0.029"/>
    <axis xyz="0 0 -1.0"/>
    <limit effort="5.0" lower="-1.0471975512" upper="1.0471975512" velocity="4.0"/>
    <dynamics damping="0.2"/>
  </joint>
  <gazebo reference="rh_THJ5">
    <provideFeedback>1</provideFeedback>
    <implicitSpringDamper>1</implicitSpringDamper>
  </gazebo>
  <transmission name="rh_thbase_transmission">
    <type>sr_mechanism_model/SimpleTransmission</type>
    <actuator name="rh_THJ5">
      <mechanicalReduction>1</mechanicalReduction>
    </actuator>
    <joint name="rh_THJ5">
      <hardwareInterface>EffortJointInterface</hardwareInterface>
      <hardwareInterface>PositionJointInterface</hardwareInterface>
    </joint>
  </transmission>
  <!-- prefix can be anything but usually is "r_" or  "l_" for right and left hands distinction -->
  <gazebo reference="rh_thbase">
    <sensor name="rh_thbase_contact" type="contact">
      <always_on>1</always_on>
      <update_rate>1000.0</update_rate>
      <contact>
        <collision>rh_thbase_collision</collision>
        <topic>rh_thbase_collision</topic>
      </contact>
      <plugin filename="libgazebo_ros_bumper.so" name="rh_thbase_gazebo_ros_bumper_controller">
        <alwaysOn>true</alwaysOn>
        <frameName>rh_thbase</frameName>
        <updateRate>100.0</updateRate>
        <bumperTopicName>contacts/rh_th/base</bumperTopicName>
      </plugin>
    </sensor>
    <selfCollide>false</selfCollide>
  </gazebo>
  <link name="rh_thproximal">
    <inertial>
      <mass value="0.040"/>
      <origin rpy="0 0 0" xyz="0 0 0.019"/>
      <inertia ixx="0.0000136" ixy="0.0" ixz="0.0" iyy="0.0000136" iyz="0.0" izz="0.00000313"/>
    </inertial>
    <visual>
      <origin rpy="0 0 0" xyz="0 0 0"/>
      <geometry name="rh_thproximal_visual">
        <mesh filename="package://sr_description/hand/model/TH3_z.dae" scale="0.001 0.001 0.001"/>
      </geometry>
      <material name="shadow_thproximal_material">
        <color rgba="0.2 0.2 0.2 1.0"/>
      </material>
    </visual>
    <collision>
      <origin rpy="0 0 0" xyz="0 0 0.020"/>
      <geometry name="rh_thproximal_collision_geom">
        <cylinder length="0.018" radius="0.012"/>
      </geometry>
    </collision>
  </link>
  <joint name="rh_THJ4" type="revolute">
    <parent link="rh_thbase"/>
    <child link="rh_thproximal"/>
    <origin rpy="0 0 0" xyz="0 0 0"/>
    <axis xyz="1.0 0 0"/>
    <limit effort="3" lower="0.0" upper="1.2217304764" velocity="4.0"/>
    <dynamics damping="0.2"/>
  </joint>
  <gazebo reference="rh_THJ4">
    <provideFeedback>1</provideFeedback>
    <implicitSpringDamper>1</implicitSpringDamper>
  </gazebo>
  <transmission name="rh_thproximal_transmission">
    <type>sr_mechanism_model/SimpleTransmission</type>
    <actuator name="rh_THJ4">
      <mechanicalReduction>1</mechanicalReduction>
    </actuator>
    <joint name="rh_THJ4">
      <hardwareInterface>EffortJointInterface</hardwareInterface>
      <hardwareInterface>PositionJointInterface</hardwareInterface>
    </joint>
  </transmission>
  <!-- prefix can be anything but usually is "r_" or  "l_" for right and left hands distinction -->
  <gazebo reference="rh_thproximal">
    <sensor name="rh_thproximal_contact" type="contact">
      <always_on>1</always_on>
      <update_rate>1000.0</update_rate>
      <contact>
        <collision>rh_thproximal_collision</collision>
        <topic>rh_thproximal_collision</topic>
      </contact>
      <plugin filename="libgazebo_ros_bumper.so" name="rh_thproximal_gazebo_ros_bumper_controller">
        <alwaysOn>true</alwaysOn>
        <frameName>rh_thproximal</frameName>
        <updateRate>100.0</updateRate>
        <bumperTopicName>contacts/rh_th/proximal</bumperTopicName>
      </plugin>
    </sensor>
    <selfCollide>false</selfCollide>
  </gazebo>
  <link name="rh_thhub">
    <inertial>
      <mass value="0.005"/>
      <origin rpy="0 0 0" xyz="0 0 0"/>
      <inertia ixx="0.000001" ixy="0.0" ixz="0.0" iyy="0.000001" iyz="0.0" izz="0.0000003"/>
    </inertial>
    <visual>
      <origin rpy="0 0 0" xyz="0 0 0"/>
      <geometry name="rh_thhub_visual">
        <box size="0.001 0.001 0.001"/>
      </geometry>
      <material name="shadow_thhub_material">
        <color rgba="0.7 0.7 0.7 1.0"/>
      </material>
    </visual>
    <collision>
      <origin rpy="0 0 0" xyz="0 0 0"/>
      <geometry name="rh_thhub_collision_geom">
        <sphere radius="0.010"/>
      </geometry>
    </collision>
  </link>
  <joint name="rh_THJ3" type="revolute">
    <parent link="rh_thproximal"/>
    <child link="rh_thhub"/>
    <origin rpy="0 0 0" xyz="0 0 0.038"/>
    <axis xyz="1 0 0"/>
    <limit effort="2.0" lower="-0.209439510239" upper="0.209439510239" velocity="4.0"/>
    <dynamics damping="0.2"/>
  </joint>
  <gazebo reference="rh_THJ3">
    <provideFeedback>1</provideFeedback>
    <implicitSpringDamper>1</implicitSpringDamper>
  </gazebo>
  <transmission name="rh_thhub_transmission">
    <type>sr_mechanism_model/SimpleTransmission</type>
    <actuator name="rh_THJ3">
      <mechanicalReduction>1</mechanicalReduction>
    </actuator>
    <joint name="rh_THJ3">
      <hardwareInterface>EffortJointInterface</hardwareInterface>
      <hardwareInterface>PositionJointInterface</hardwareInterface>
    </joint>
  </transmission>
  <!-- prefix can be anything but usually is "r_" or  "l_" for right and left hands distinction -->
  <gazebo reference="rh_thhub">
    <sensor name="rh_thhub_contact" type="contact">
      <always_on>1</always_on>
      <update_rate>1000.0</update_rate>
      <contact>
        <collision>rh_thhub_collision</collision>
        <topic>rh_thhub_collision</topic>
      </contact>
      <plugin filename="libgazebo_ros_bumper.so" name="rh_thhub_gazebo_ros_bumper_controller">
        <alwaysOn>true</alwaysOn>
        <frameName>rh_thhub</frameName>
        <updateRate>100.0</updateRate>
        <bumperTopicName>contacts/rh_th/hub</bumperTopicName>
      </plugin>
    </sensor>
    <selfCollide>true</selfCollide>
  </gazebo>
  <link name="rh_thmiddle">
    <inertial>
      <mass value="0.020"/>
      <origin rpy="0 0 0" xyz="0 0 0.016"/>
      <inertia ixx="0.0000051" ixy="0.0" ixz="0.0" iyy="0.0000051" iyz="0.0" izz="0.00000121"/>
    </inertial>
    <visual>
      <origin rpy="0 0 0" xyz="0 0 0"/>
      <geometry name="rh_thmiddle_visual">
        <mesh filename="package://sr_description/hand/model/TH2_z.dae" scale="0.001 0.001 0.001"/>
      </geometry>
      <material name="shadow_thmiddle_material">
        <color rgba="0.2 0.2 0.2 1.0"/>
      </material>
    </visual>
    <collision>
      <origin rpy="0 0 0" xyz="0 0 0.012"/>
      <geometry name="rh_thmiddle_collision_geom">
        <cylinder length="0.018" radius="0.011"/>
      </geometry>
    </collision>
    <collision>
      <origin rpy="0 0 0" xyz="0 0 0.019"/>
      <geometry>
        <sphere radius="0.011"/>
      </geometry>
    </collision>
  </link>
  <joint name="rh_THJ2" type="revolute">
    <parent link="rh_thhub"/>
    <child link="rh_thmiddle"/>
    <origin rpy="0 0 0" xyz="0 0 0"/>
    <axis xyz="0 -1 0"/>
    <limit effort="2.0" lower="-0.698131700798" upper="0.698131700798" velocity="2.0"/>
    <dynamics damping="0.1"/>
  </joint>
  <gazebo reference="rh_THJ2">
    <provideFeedback>1</provideFeedback>
    <implicitSpringDamper>1</implicitSpringDamper>
  </gazebo>
  <transmission name="rh_thmiddle_transmission">
    <type>sr_mechanism_model/SimpleTransmission</type>
    <actuator name="rh_THJ2">
      <mechanicalReduction>1</mechanicalReduction>
    </actuator>
    <joint name="rh_THJ2">
      <hardwareInterface>EffortJointInterface</hardwareInterface>
      <hardwareInterface>PositionJointInterface</hardwareInterface>
    </joint>
  </transmission>
  <!-- prefix can be anything but usually is "r_" or  "l_" for right and left hands distinction -->
  <gazebo reference="rh_thmiddle">
    <sensor name="rh_thmiddle_contact" type="contact">
      <always_on>1</always_on>
      <update_rate>1000.0</update_rate>
      <contact>
        <collision>rh_thmiddle_collision</collision>
        <topic>rh_thmiddle_collision</topic>
      </contact>
      <plugin filename="libgazebo_ros_bumper.so" name="rh_thmiddle_gazebo_ros_bumper_controller">
        <alwaysOn>true</alwaysOn>
        <frameName>rh_thmiddle</frameName>
        <updateRate>100.0</updateRate>
        <bumperTopicName>contacts/rh_th/middle</bumperTopicName>
      </plugin>
    </sensor>
    <selfCollide>true</selfCollide>
  </gazebo>
  <!-- common -->
  <link name="rh_thdistal">
    <inertial>
      <mass value="0.016"/>
      <origin rpy="0 0 0" xyz="0 0 0.01375"/>
      <inertia ixx="0.0000021" ixy="0.0" ixz="0.0" iyy="0.0000022" iyz="0.0" izz="0.000001"/>
    </inertial>
    <visual>
      <origin rpy="0 0 0" xyz="0 0 0"/>
      <geometry name="rh_thdistal_visual">
        <!-- Standard distal  -->
        <mesh filename="package://sr_description/hand/model/TH1_z.dae" scale="0.001 0.001 0.001"/>
      </geometry>
      <material name="shadow_thmiddle_material">
        <color rgba="0.2 0.2 0.2 1.0"/>
      </material>
    </visual>
    <collision>
      <origin rpy="0 0 0" xyz="0 0 0"/>
      <geometry name="rh_thmiddle_collision_geom">
        <!-- Standard distal  -->
        <mesh filename="package://sr_description/hand/model/TH1_z.dae" scale="0.001 0.001 0.001"/>
        <!--      <box size="0.015 0.015 0.015" /> -->
      </geometry>
    </collision>
  </link>
  <joint name="rh_THJ1" type="revolute">
    <parent link="rh_thmiddle"/>
    <child link="rh_thdistal"/>
    <origin rpy="0 0 -1.57079632679" xyz="0 0 0.032"/>
    <axis xyz="1 0 0"/>
    <limit effort="1.0" lower="0" upper="1.57079632679" velocity="4.0"/>
    <dynamics damping="0.2"/>
  </joint>
  <gazebo reference="rh_THJ1">
    <provideFeedback>1</provideFeedback>
    <implicitSpringDamper>1</implicitSpringDamper>
  </gazebo>
  <link name="rh_thtip">
    <inertial>
      <mass value="0.001"/>
      <inertia ixx="0.0" ixy="0.0" ixz="0.0" iyy="0.0" iyz="0.0" izz="0.0"/>
    </inertial>
  </link>
  <joint name="rh_thtip" type="fixed">
    <parent link="rh_thdistal"/>
    <child link="rh_thtip"/>
    <origin rpy="0 0 0" xyz="0 0 0.0275"/>
  </joint>
  <!-- prefix can be anything but usually is "r_" or  "l_" for right and left hands distinction -->
  <gazebo reference="rh_thdistal">
    <sensor name="rh_thdistal_contact" type="contact">
      <always_on>1</always_on>
      <update_rate>1000.0</update_rate>
      <contact>
        <collision>rh_thdistal_collision</collision>
        <topic>rh_thdistal_collision</topic>
      </contact>
      <plugin filename="libgazebo_ros_bumper.so" name="rh_thdistal_gazebo_ros_bumper_controller">
        <alwaysOn>true</alwaysOn>
        <frameName>rh_thdistal</frameName>
        <updateRate>100.0</updateRate>
        <bumperTopicName>contacts/rh_th/distal</bumperTopicName>
      </plugin>
    </sensor>
    <mu1 value="500.0"/>
    <mu2 value="500.0"/>
    <kp value="10000000.0"/>
    <kd value="1.0"/>
    <selfCollide>true</selfCollide>
  </gazebo>
  <transmission name="rh_thdistal_transmission">
    <type>sr_mechanism_model/SimpleTransmission</type>
    <actuator name="rh_THJ1">
      <mechanicalReduction>1</mechanicalReduction>
    </actuator>
    <joint name="rh_THJ1">
      <hardwareInterface>EffortJointInterface</hardwareInterface>
      <hardwareInterface>PositionJointInterface</hardwareInterface>
    </joint>
  </transmission>
  <link name="l_shoulder_base_link">
    <visual>
      <geometry>
        <mesh filename="package://inmoov_meshes/meshes/l_shoulder_base.stl" scale="0.001 0.001 0.001"/>
      </geometry>
      <origin rpy="0 0 0" xyz="0 0 0"/>
      <material name="cframe">
        <color rgba="0.40 0.40 0.40 1"/>
      </material>
    </visual>
    <inertial>
      <mass value="266.52696875"/>
      <inertia ixx="0.35041024" ixy="0.0057351615" ixz="-0.011193821" iyy="0.390885728" iyz="-0.045447508" izz="0.27145872"/>
    </inertial>
  </link>
  <link name="l_shoulder_link">
    <visual>
      <geometry>
        <mesh filename="package://inmoov_meshes/meshes/l_shoulder.stl" scale="0.001 0.001 0.001"/>
      </geometry>
      <origin rpy="0 0 0" xyz="0 0 0"/>
      <material name="cframe">
        <color rgba="0.40 0.40 0.40 1"/>
      </material>
    </visual>
    <inertial>
      <mass value="322.44334375"/>
      <inertia ixx="0.601346048" ixy="-0.003437744" ixz="-0.011761914" iyy="0.473865952" iyz="0.11427704" izz="0.50095152"/>
    </inertial>
  </link>
  <link name="l_bicep_link_aux_0"/>
  <link name="l_bicep_link_aux_1"/>
  <link name="l_bicep_link">
    <visual>
      <geometry>
        <mesh filename="package://inmoov_meshes/meshes/bicep.stl" scale="0.001 0.001 0.001"/>
      </geometry>
      <origin rpy="0 0 0" xyz="0 0 0"/>
      <material name="cframe">
        <color rgba="0.40 0.40 0.40 1"/>
      </material>
    </visual>
    <inertial>
      <mass value="281.91265625"/>
      <inertia ixx="1.283355392" ixy="-0.000200782203125" ixz="-0.224559104" iyy="1.399255168" iyz="0.0006545236875" izz="0.416621216"/>
    </inertial>
  </link>
  <link name="l_bicepcover_link">
    <visual>
      <geometry>
        <mesh filename="package://inmoov_meshes/meshes/bicepcover.stl" scale="0.001 0.001 0.001"/>
      </geometry>
      <origin rpy="0 0 0" xyz="0 0 0"/>
      <material name="ccover">
        <color rgba="0.75 0.75 0.75 1.0"/>
      </material>
    </visual>
    <inertial>
      <mass value="176.269609375"/>
      <inertia ixx="0.536349632" ixy="0.0009665334375" ixz="-0.069306768" iyy="0.625805568" iyz="0.0005666358125" izz="0.44191648"/>
    </inertial>
  </link>
  <link name="l_forearm_link_aux"/>
  <link name="l_forearm_link">
    <visual>
      <geometry>
        <mesh filename="package://inmoov_meshes/meshes/l_forearm.stl" scale="0.001 0.001 0.001"/>
      </geometry>
      <origin rpy="0 0 0" xyz="-0.001 0 0"/>
      <material name="ccover">
        <color rgba="0.75 0.75 0.75 1.0"/>
      </material>
    </visual>
    <inertial>
      <mass value="401.76659375"/>
      <inertia ixx="3.242308096" ixy="-0.050011216" ixz="-0.143185152" iyy="3.242510848" iyz="-0.086288992" izz="0.58458784"/>
    </inertial>
  </link>
  <joint name="l_shoulder_lift_joint_old" type="fixed">
    <origin rpy="0 0 0" xyz="0 0.012 -0.04"/>
    <parent link="l_shoulder_base_link"/>
    <child link="l_shoulder_link"/>
  </joint>
  <joint name="l_shoulder_out_joint" type="revolute">
    <axis xyz="1 0 0"/>
    <limit effort="1000.0" lower="-1.57079632679" upper="1.57079632679" velocity="1745.32925199"/>
    <!-- <origin rpy="0 0 0" xyz="0 0 0"/> -->
    <origin rpy="0 0 0" xyz="0 0.066 -0.06"/>
    <parent link="l_shoulder_link"/>
    <child link="l_bicep_link_aux_0"/>
  </joint>
  <joint name="l_shoulder_lift_joint" type="revolute">
    <axis xyz="0 1 0"/>
    <limit effort="1000.0" lower="-1.57079632679" upper="1.57079632679" velocity="1745.32925199"/>
    <origin rpy="0 0 0" xyz="0 0 0"/>
    <parent link="l_bicep_link_aux_0"/>
    <child link="l_bicep_link_aux_1"/>
  </joint>
  <joint name="l_upper_arm_roll_joint" type="revolute">
    <axis xyz="0 0 1"/>
    <limit effort="1000.0" lower="-1.57079632679" upper="1.57079632679" velocity="1745.32925199"/>
    <origin rpy="0 0 0" xyz="0 0 0"/>
    <parent link="l_bicep_link_aux_1"/>
    <child link="l_bicep_link"/>
  </joint>
  <joint name="l_elbow_flex_joint" type="revolute">
    <axis xyz="0 1 0"/>
    <limit effort="1000.0" lower="-3.14159265359" upper="0.0" velocity="1745.32925199"/>
    <origin rpy="0 0 0" xyz="-0.03 0 -0.225"/>
    <parent link="l_bicep_link"/>
    <child link="l_forearm_link_aux"/>
  </joint>
  <joint name="l_elbow_roll_joint" type="revolute">
    <axis xyz="0 0 1"/>
    <limit effort="1000.0" lower="-1.57079632679" upper="1.57079632679" velocity="1745.32925199"/>
    <origin rpy="0 0 0" xyz="0.0 0 0.0"/>
    <parent link="l_forearm_link_aux"/>
    <child link="l_forearm_link"/>
  </joint>
  <joint name="l_bicepcover_joint" type="fixed">
    <origin rpy="0 0 0" xyz="0 0 0"/>
    <parent link="l_bicep_link"/>
    <child link="l_bicepcover_link"/>
  </joint>
  <!-- <joint name="l_shoulder_out_joint" type="revolute">
   <axis xyz="1 0 0"/>
   <limit effort="1000.0" lower="${l_shoulder_out_joint_lower}" upper="${l_shoulder_out_joint_upper}" velocity="${l_shoulder_out_joint_velocity}" />
   <origin rpy="0 0 0" xyz="0 0.14 0.3"/>
   <parent link="torso_link"/>
   <child link="l_shoulder_base_link"/>
  </joint> -->
  <joint name="l_shoulder_out_joint_old" type="fixed">
    <origin rpy="0 0 0" xyz="0 0.14 0.3"/>
    <parent link="torso_link"/>
    <child link="l_shoulder_base_link"/>
  </joint>
  <link name="l_hand_link"/>
  <joint name="l_wrist_roll_joint" type="fixed">
    <origin rpy="3.14159265359 0 0" xyz="-0.015 0.01  -0.3"/>
    <parent link="l_forearm_link"/>
    <child link="l_hand_link"/>
  </joint>
</robot>

